Workbook

Sheet Serie
A1: Serie para el grafico
A2: Graficar B (fecha) contra C, D, E, F y G. Las columnas D a G estan en unidades de ciclo para que compartan eje con el ciclo; la columna H es la inflacion en % por si se quiere un eje secundario legible.
A4: codmes | B4: fecha | C4: Ciclo 5 bancos | D4: Inflacion obs (mes 0) | E4: Proy base | F4: Proy optimista | G4: Proy pesimista | H4: Inflacion % | I4: origen | K4: infl base % | L4: infl opt % | M4: infl pes %
A5: 201902 | B5: 43497 | C5: =Entidades!R5 | D5: =IF(H5="","",Parametros!$B$5*(H5-Parametros!$B$6)) | I5: observado
A6: 201903 | B6: 43525 | C6: =Entidades!R6 | D6: =IF(H6="","",Parametros!$B$5*(H6-Parametros!$B$6)) | I6: observado
A7: 201904 | B7: 43556 | C7: =Entidades!R7 | D7: =IF(H7="","",Parametros!$B$5*(H7-Parametros!$B$6)) | I7: observado
A8: 201905 | B8: 43586 | C8: =Entidades!R8 | D8: =IF(H8="","",Parametros!$B$5*(H8-Parametros!$B$6)) | I8: observado
A9: 201906 | B9: 43617 | C9: =Entidades!R9 | D9: =IF(H9="","",Parametros!$B$5*(H9-Parametros!$B$6)) | I9: observado
A10: 201907 | B10: 43647 | C10: =Entidades!R10 | D10: =IF(H10="","",Parametros!$B$5*(H10-Parametros!$B$6)) | I10: observado
A11: 201908 | B11: 43678 | C11: =Entidades!R11 | D11: =IF(H11="","",Parametros!$B$5*(H11-Parametros!$B$6)) | I11: observado
A12: 201909 | B12: 43709 | C12: =Entidades!R12 | D12: =IF(H12="","",Parametros!$B$5*(H12-Parametros!$B$6)) | I12: observado
A13: 201910 | B13: 43739 | C13: =Entidades!R13 | D13: =IF(H13="","",Parametros!$B$5*(H13-Parametros!$B$6)) | I13: observado
A14: 201911 | B14: 43770 | C14: =Entidades!R14 | D14: =IF(H14="","",Parametros!$B$5*(H14-Parametros!$B$6)) | I14: observado
A15: 201912 | B15: 43800 | C15: =Entidades!R15 | D15: =IF(H15="","",Parametros!$B$5*(H15-Parametros!$B$6)) | I15: observado
A16: 202001 | B16: 43831 | C16: =Entidades!R16 | D16: =IF(H16="","",Parametros!$B$5*(H16-Parametros!$B$6)) | I16: observado
A17: 202002 | B17: 43862 | C17: =Entidades!R17 | D17: =IF(H17="","",Parametros!$B$5*(H17-Parametros!$B$6)) | H17: 1.9040378 | I17: observado
A18: 202003 | B18: 43891 | C18: =Entidades!R18 | D18: =IF(H18="","",Parametros!$B$5*(H18-Parametros!$B$6)) | H18: 1.821533 | I18: observado
A19: 202004 | B19: 43922 | D19: =IF(H19="","",Parametros!$B$5*(H19-Parametros!$B$6)) | H19: 1.7244898 | I19: observado
A20: 202005 | B20: 43952 | D20: =IF(H20="","",Parametros!$B$5*(H20-Parametros!$B$6)) | H20: 1.7819198 | I20: observado
A21: 202006 | B21: 43983 | D21: =IF(H21="","",Parametros!$B$5*(H21-Parametros!$B$6)) | H21: 1.5987324 | I21: observado
A22: 202007 | B22: 44013 | C22: =Entidades!R19 | D22: =IF(H22="","",Parametros!$B$5*(H22-Parametros!$B$6)) | H22: 1.8616957 | I22: observado
A23: 202008 | B23: 44044 | D23: =IF(H23="","",Parametros!$B$5*(H23-Parametros!$B$6)) | H23: 1.6873982 | I23: observado
A24: 202009 | B24: 44075 | D24: =IF(H24="","",Parametros!$B$5*(H24-Parametros!$B$6)) | H24: 1.8195539 | I24: observado
A25: 202010 | B25: 44105 | C25: =Entidades!R20 | D25: =IF(H25="","",Parametros!$B$5*(H25-Parametros!$B$6)) | H25: 1.7240004 | I25: observado
A26: 202011 | B26: 44136 | C26: =Entidades!R21 | D26: =IF(H26="","",Parametros!$B$5*(H26-Parametros!$B$6)) | H26: 2.1422097 | I26: observado
A27: 202012 | B27: 44166 | C27: =Entidades!R22 | D27: =IF(H27="","",Parametros!$B$5*(H27-Parametros!$B$6)) | H27: 1.9732322 | I27: observado
A28: 202101 | B28: 44197 | C28: =Entidades!R23 | D28: =IF(H28="","",Parametros!$B$5*(H28-Parametros!$B$6)) | H28: 2.2013647 | I28: observado
A29: 202102 | B29: 44228 | C29: =Entidades!R24 | D29: =IF(H29="","",Parametros!$B$5*(H29-Parametros!$B$6)) | H29: 2.0445709 | I29: observado
A30: 202103 | B30: 44256 | C30: =Entidades!R25 | D30: =IF(H30="","",Parametros!$B$5*(H30-Parametros!$B$6)) | H30: 2.1593131 | I30: observado
A31: 202104 | B31: 44287 | C31: =Entidades!R26 | D31: =IF(H31="","",Parametros!$B$5*(H31-Parametros!$B$6)) | H31: 2.1007485 | I31: observado
A32: 202105 | B32: 44317 | C32: =Entidades!R27 | D32: =IF(H32="","",Parametros!$B$5*(H32-Parametros!$B$6)) | H32: 2.1124636 | I32: observado
A33: 202106 | B33: 44348 | C33: =Entidades!R28 | D33: =IF(H33="","",Parametros!$B$5*(H33-Parametros!$B$6)) | H33: 2.9269906 | I33: observado
A34: 202107 | B34: 44378 | C34: =Entidades!R29 | D34: =IF(H34="","",Parametros!$B$5*(H34-Parametros!$B$6)) | H34: 3.5179925 | I34: observado
A35: 202108 | B35: 44409 | C35: =Entidades!R30 | D35: =IF(H35="","",Parametros!$B$5*(H35-Parametros!$B$6)) | H35: 4.7342557 | I35: observado
A36: 202109 | B36: 44440 | C36: =Entidades!R31 | D36: =IF(H36="","",Parametros!$B$5*(H36-Parametros!$B$6)) | H36: 5.1856859 | I36: observado
... A81: 202506 | B81: 45809 | C81: =Entidades!R76 | D81: =IF(H81="","",Parametros!$B$5*(H81-Parametros!$B$6)) | H81: 1.697547 | I81: observado
A82: 202507 | B82: 45839 | D82: =IF(H82="","",Parametros!$B$5*(H82-Parametros!$B$6)) | H82: 1.7003977 | I82: observado
A83: 202508 | B83: 45870 | D83: =IF(H83="","",Parametros!$B$5*(H83-Parametros!$B$6)) | H83: 1.0907218 | I83: observado
A84: 202509 | B84: 45901 | D84: =IF(H84="","",Parametros!$B$5*(H84-Parametros!$B$6)) | H84: 1.2276226 | I84: observado
A85: 202510 | B85: 45931 | D85: =IF(H85="","",Parametros!$B$5*(H85-Parametros!$B$6)) | H85: 1.1625606 | I85: observado
...

Sheet Parametros
A1: Parametros del factor macro
A2: En azul los valores fijos del pipeline. Todo lo demas del libro los referencia.
A4: Parametro | B4: Valor | C4: Que es | D4: Fuente
A5: beta | B5: 0.0601 | C5: lleva la inflacion a unidades de ciclo | D5: macro_model.json
A6: mu | B6: 4.5240631 | C6: inflacion media del panel; con infl = mu el ciclo es 0 | D6: macro_model.json
A7: carga | B7: 0.72842353 | C7: lleva el ciclo al probit de la mora | D7: macro_model.json
A8: centro | B8: -0.049974247 | C8: centrado del ft exportado | D8: macro_model.json
A9: rho | B9: 0.0332 | C9: correlacion de activos (piso; el panel midio 0.0244) | D9: vasicek_rho.json
A10: lambda | B10: 1 | C10: sensibilidad al ciclo (tope: el MLE pide 2.60) | D10: config.LAMBDA_PIT
A11: LRA | B11: 0.069833796 | C11: mora de largo plazo de la cartera | D11: lra.json
A12: raiz(rho) | B12: =SQRT(B9) | C12: transmision al probit
A13: raiz(1-rho) | B13: =SQRT(1-B9)

Sheet Entidades
A1: De la mora de los 5 bancos al ciclo comun
A2: A cada banco se le resta su propio nivel (en escala probit). El promedio de esos desvios es el ciclo. Las columnas en azul son dato; el resto son formulas.
A4: codmes | B4: fecha | C4: RD BCP | D4: RD Interbank | E4: RD Scotiabank | F4: RD BBVA | G4: RD Falabella | H4: probit BCP | I4: probit Interbank | J4: probit Scotiabank | K4: probit BBVA | L4: probit Falabella | M4: desvio BCP | N4: desvio Interbank | O4: desvio Scotiabank | P4: desvio BBVA | Q4: desvio Falabella | R4: CICLO
A5: 201902 | B5: 43497 | C5: 0.096781744 | D5: 0.15975584 | E5: 0.1693038 | F5: 0.058181818 | G5: 0.25495942 | H5: =NORMSINV(C5) | I5: =NORMSINV(D5) | J5: =NORMSINV(E5) | K5: =NORMSINV(F5) | L5: =NORMSINV(G5) | M5: =H5-AVERAGE(H$5:H$76) | N5: =I5-AVERAGE(I$5:I$76) | O5: =J5-AVERAGE(J$5:J$76) | P5: =K5-AVERAGE(K$5:K$76) | Q5: =L5-AVERAGE(L$5:L$76) | R5: =AVERAGE(M5:Q5)
A6: 201903 | B6: 43525 | C6: 0.092345079 | D6: 0.16275259 | E6: 0.14417178 | F6: 0.067986799 | G6: 0.27319588 | H6: =NORMSINV(C6) | I6: =NORMSINV(D6) | J6: =NORMSINV(E6) | K6: =NORMSINV(F6) | L6: =NORMSINV(G6) | M6: =H6-AVERAGE(H$5:H$76) | N6: =I6-AVERAGE(I$5:I$76) | O6: =J6-AVERAGE(J$5:J$76) | P6: =K6-AVERAGE(K$5:K$76) | Q6: =L6-AVERAGE(L$5:L$76) | R6: =AVERAGE(M6:Q6)
A7: 201904 | B7: 43556 | C7: 0.08672625 | D7: 0.16262404 | E7: 0.12385321 | F7: 0.047043011 | G7: 0.2984096 | H7: =NORMSINV(C7) | I7: =NORMSINV(D7) | J7: =NORMSINV(E7) | K7: =NORMSINV(F7) | L7: =NORMSINV(G7) | M7: =H7-AVERAGE(H$5:H$76) | N7: =I7-AVERAGE(I$5:I$76) | O7: =J7-AVERAGE(J$5:J$76) | P7: =K7-AVERAGE(K$5:K$76) | Q7: =L7-AVERAGE(L$5:L$76) | R7: =AVERAGE(M7:Q7)
A8: 201905 | B8: 43586 | C8: 0.07552717 | D8: 0.15725562 | E8: 0.14343708 | F8: 0.048272079 | G8: 0.29285099 | H8: =NORMSINV(C8) | I8: =NORMSINV(D8) | J8: =NORMSINV(E8) | K8: =NORMSINV(F8) | L8: =NORMSINV(G8) | M8: =H8-AVERAGE(H$5:H$76) | N8: =I8-AVERAGE(I$5:I$76) | O8: =J8-AVERAGE(J$5:J$76) | P8: =K8-AVERAGE(K$5:K$76) | Q8: =L8-AVERAGE(L$5:L$76) | R8: =AVERAGE(M8:Q8)
A9: 201906 | B9: 43617 | C9: 0.073392358 | D9: 0.1366797 | E9: 0.11229947 | F9: 0.04381949 | G9: 0.30811674 | H9: =NORMSINV(C9) | I9: =NORMSINV(D9) | J9: =NORMSINV(E9) | K9: =NORMSINV(F9) | L9: =NORMSINV(G9) | M9: =H9-AVERAGE(H$5:H$76) | N9: =I9-AVERAGE(I$5:I$76) | O9: =J9-AVERAGE(J$5:J$76) | P9: =K9-AVERAGE(K$5:K$76) | Q9: =L9-AVERAGE(L$5:L$76) | R9: =AVERAGE(M9:Q9)
A10: 201907 | B10: 43647 | C10: 0.08175583 | D10: 0.13394378 | E10: 0.081027668 | F10: 0.031676413 | G10: 0.34870089 | H10: =NORMSINV(C10) | I10: =NORMSINV(D10) | J10: =NORMSINV(E10) | K10: =NORMSINV(F10) | L10: =NORMSINV(G10) | M10: =H10-AVERAGE(H$5:H$76) | N10: =I10-AVERAGE(I$5:I$76) | O10: =J10-AVERAGE(J$5:J$76) | P10: =K10-AVERAGE(K$5:K$76) | Q10: =L10-AVERAGE(L$5:L$76) | R10: =AVERAGE(M10:Q10)
A11: 201908 | B11: 43678 | C11: 0.067405808 | D11: 0.10716804 | E11: 0.076162216 | F11: 0.031862745 | G11: 0.34867997 | H11: =NORMSINV(C11) | I11: =NORMSINV(D11) | J11: =NORMSINV(E11) | K11: =NORMSINV(F11) | L11: =NORMSINV(G11) | M11: =H11-AVERAGE(H$5:H$76) | N11: =I11-AVERAGE(I$5:I$76) | O11: =J11-AVERAGE(J$5:J$76) | P11: =K11-AVERAGE(K$5:K$76) | Q11: =L11-AVERAGE(L$5:L$76) | R11: =AVERAGE(M11:Q11)
A12: 201909 | B12: 43709 | C12: 0.09070776 | D12: 0.11435745 | E12: 0.091187739 | F12: 0.029858565 | G12: 0.34911019 | H12: =NORMSINV(C12) | I12: =NORMSINV(D12) | J12: =NORMSINV(E12) | K12: =NORMSINV(F12) | L12: =NORMSINV(G12) | M12: =H12-AVERAGE(H$5:H$76) | N12: =I12-AVERAGE(I$5:I$76) | O12: =J12-AVERAGE(J$5:J$76) | P12: =K12-AVERAGE(K$5:K$76) | Q12: =L12-AVERAGE(L$5:L$76) | R12: =AVERAGE(M12:Q12)
A13: 201910 | B13: 43739 | C13: 0.095429872 | D13: 0.13814639 | E13: 0.099142551 | F13: 0.024961793 | G13: 0.34593924 | H13: =NORMSINV(C13) | I13: =NORMSINV(D13) | J13: =NORMSINV(E13) | K13: =NORMSINV(F13) | L13: =NORMSINV(G13) | M13: =H13-AVERAGE(H$5:H$76) | N13: =I13-AVERAGE(I$5:I$76) | O13: =J13-AVERAGE(J$5:J$76) | P13: =K13-AVERAGE(K$5:K$76) | Q13: =L13-AVERAGE(L$5:L$76) | R13: =AVERAGE(M13:Q13)
A14: 201911 | B14: 43770 | C14: 0.099036403 | D14: 0.1412615 | E14: 0.13064516 | F14: 0.047018905 | G14: 0.28189521 | H14: =NORMSINV(C14) | I14: =NORMSINV(D14) | J14: =NORMSINV(E14) | K14: =NORMSINV(F14) | L14: =NORMSINV(G14) | M14: =H14-AVERAGE(H$5:H$76) | N14: =I14-AVERAGE(I$5:I$76) | O14: =J14-AVERAGE(J$5:J$76) | P14: =K14-AVERAGE(K$5:K$76) | Q14: =L14-AVERAGE(L$5:L$76) | R14: =AVERAGE(M14:Q14)
A15: 201912 | B15: 43800 | C15: 0.12929438 | D15: 0.14005974 | E15: 0.1530877 | F15: 0.054699947 | G15: 0.29376227 | H15: =NORMSINV(C15) | I15: =NORMSINV(D15) | J15: =NORMSINV(E15) | K15: =NORMSINV(F15) | L15: =NORMSINV(G15) | M15: =H15-AVERAGE(H$5:H$76) | N15: =I15-AVERAGE(I$5:I$76) | O15: =J15-AVERAGE(J$5:J$76) | P15: =K15-AVERAGE(K$5:K$76) | Q15: =L15-AVERAGE(L$5:L$76) | R15: =AVERAGE(M15:Q15)
A16: 202001 | B16: 43831 | C16: 0.12174316 | D16: 0.12163073 | E16: 0.15225744 | F16: 0.049066667 | G16: 0.26497504 | H16: =NORMSINV(C16) | I16: =NORMSINV(D16) | J16: =NORMSINV(E16) | K16: =NORMSINV(F16) | L16: =NORMSINV(G16) | M16: =H16-AVERAGE(H$5:H$76) | N16: =I16-AVERAGE(I$5:I$76) | O16: =J16-AVERAGE(J$5:J$76) | P16: =K16-AVERAGE(K$5:K$76) | Q16: =L16-AVERAGE(L$5:L$76) | R16: =AVERAGE(M16:Q16)
... A76: 202506 | B76: 45809 | C76: 0.027697042 | D76: 0.054448871 | E76: 0.074152542 | F76: 0.13167825 | G76: 0.13942127 | H76: =NORMSINV(C76) | I76: =NORMSINV(D76) | J76: =NORMSINV(E76) | K76: =NORMSINV(F76) | L76: =NORMSINV(G76) | M76: =H76-AVERAGE(H$5:H$76) | N76: =I76-AVERAGE(I$5:I$76) | O76: =J76-AVERAGE(J$5:J$76) | P76: =K76-AVERAGE(K$5:K$76) | Q76: =L76-AVERAGE(L$5:L$76) | R76: =AVERAGE(M76:Q76)

Sheet LEEME
A1: Como rehacer el grafico
A3: HOJA "Serie" - es la que se grafica.
A4: Insertar grafico de LINEAS con la columna B (fecha) como eje X.
A5: Series: C (ciclo), D (inflacion observada), E (proy base), F (optimista), G (pesimista).
A6: Sugerido: C en verde grueso, D punteada oscura, E punteada fina, F y G finas para la banda.
A8: POR QUE COMPARTEN EJE.
A9: El ciclo esta en unidades de probit y la inflacion en %. Las columnas D a G no son la
A10: inflacion cruda: son beta x (inflacion - mu), que es justo la conversion a unidades de
A11: ciclo. Por eso se pueden dibujar en el mismo eje sin trucar escalas.
A12: La columna H tiene la inflacion en % por si se quiere un eje secundario legible.
A14: MES 0.
A15: La inflacion de cada fila es la del MISMO mes que la mora. Sin rezago y sin media movil.
... A30: TTC de cada cliente, que no es una serie mensual.
