Workbook

Sheet Metodologia
B2: Score indirecto FEN por % de empleo — Metodologia
B4: Que mide: la exposicion del EMPLEO de cada distrito a la contraccion sectorial que proyecta Apoyo bajo el golpe FEN (2026).
B6: 1) Categorias = los 8 sectores economicos de Apoyo (Agropecuario, Pesca, Mineria, Manufactura, Electricidad y agua, Construccion, Comercio, Servicios).
B7: Las 21 ramas del Censo 2017 (PEA ocupada, Cuadro 11) se reagrupan a esos 8 sectores (ver hoja 'Mapeo CIIU'). La pesca se separa del agro con el bisturi CENEC (pesca_personal).
B9: 2) Factor por sector = la CAIDA del base de Apoyo 2026 (Tabla B.2, var% real), con signo invertido: factor = -(var%). Positivo = contraccion = estres. Ver hoja 'Factores' (editable).
B10: El base 2026 ya incorpora el FEN (mar caliente): Pesca -31,1%, Agro -1,5%. En 2027 ambos recuperan, por eso se usa 2026.
B12: 3) Formula (hoja 'Score s'):
B13: s[distrito] = Sum_sectores ( %empleo_del_distrito_en_el_sector x factor_del_sector )
B14: %empleo del Censo (suma 100% por distrito) x factor de Apoyo. s alto = mas contraccion = mas estres FEN. s negativo = el distrito crece (sectores en expansion pesan mas).
B16: Trazabilidad: 'Empleo Censo' (data) -> 'Score s' (formulas =SUMPRODUCT que referencian 'Factores'). Editar un factor recalcula todos los distritos.
B18: Fuentes: Censo Nacional 2017 (INEI, Cuadro 11) para el empleo por rama x distrito; Proyecciones Apoyo Consultoria (Set-2026), Tabla B.2, escenario base, para la caida sectorial 2026.

Sheet Factores
A1: Sector economico (Apoyo) | B1: Agropecuario | C1: Pesca | D1: Mineria e hidrocarburos | E1: Manufactura | F1: Electricidad y agua | G1: Construccion | H1: Comercio | I1: Servicios
A2: var% real base 2026 (Tabla B.2) | B2: -0.015 | C2: -0.311 | D2: -0.008 | E2: -0.015 | F2: 0.044 | G2: 0.094 | H2: 0.057 | I2: 0.032
A3: FACTOR = -(var%) [editable] | B3: =-B2 | C3: =-C2 | D3: =-D2 | E3: =-E2 | F3: =-F2 | G3: =-G2 | H3: =-H2 | I3: =-I2
A5: Nota: fila 3 es el peso que usa 'Score s'. Positivo = el sector cae (estres). Editar aqui recalcula todo.
A7: PEOR (imputacion sin dato: PEA=0) | B7: =MAXIFS('Score s'!$L$2:$L$1892,'Score s'!$M$2:$M$1892,">0")
A8: Regla: distrito sin PEA (post-2017) -> se le da el PEOR caso (conservador), no un neutro.

Sheet Mapeo CIIU
A1: Rama del Censo 2017 (CIIU) | B1: Sector Apoyo
A2: Agricultura, ganaderia, silvicultura y pesca | B2: Agropecuario (+ Pesca via CENEC)
A3: Explotacion de minas y canteras | B3: Mineria e hidrocarburos
A4: Industrias manufactureras | B4: Manufactura
A5: Suministro de electricidad, gas | B5: Electricidad y agua
A6: Suministro de agua; saneamiento | B6: Electricidad y agua
A7: Construccion | B7: Construccion
A8: Comercio y reparacion de vehiculos | B8: Comercio
A9: Transporte y almacenamiento | B9: Servicios
A10: Alojamiento y servicio de comidas | B10: Servicios
A11: Informacion y comunicaciones | B11: Servicios
A12: Actividades financieras y de seguros | B12: Servicios
... A22: Organizaciones extraterritoriales | B22: Servicios
A24: La unica rama que se parte es 'agricultura...y pesca' (combinada en Censo, separada en Apoyo) via pesca_personal (CENEC).

Sheet Empleo Censo
A1: ubigeo | B1: departamento | C1: provincia | D1: distrito | E1: PEA ocup. | F1: % Pesca (CENEC) | G1: Agricultura, ganaderia, silvicultura y pesca | H1: Minas y canteras | I1: Industrias manufactureras | J1: Sum. electricidad/gas | K1: Sum. agua/saneamiento | L1: Construccion | M1: Comercio y reparacion | N1: Transporte y almacen. | O1: Alojamiento y comidas | P1: Informacion y comunic. | Q1: Financieras y seguros | R1: Inmobiliarias | S1: Profesionales/tecnicas | T1: Servicios administrativos | U1: Adm. publica y defensa | V1: Ensenanza | W1: Salud y asist. social | X1: Artisticas/entretenim. | Y1: Otras act. de servicios | Z1: Hogares empleadores | AA1: Organizaciones extraterr.
A2: 100101 | B2: HUANUCO | C2: HUANUCO | D2: HUANUCO | E2: 37683 | F2: 0 | G2: 7.1 | H2: 0.36 | I2: 4.67 | J2: 0.06 | K2: 0.21 | L2: 7.76 | M2: 25.44 | N2: 10.82 | O2: 6.71 | P2: 0.96 | Q2: 1.05 | R2: 0.12 | S2: 7.42 | T2: 2.42 | U2: 5.3 | V2: 9.96 | W2: 4.1 | X2: 1.19 | Y2: 3.13 | Z2: 1.21 | AA2: 0
A3: 100102 | B3: HUANUCO | C3: HUANUCO | D3: AMARILIS | E3: 33541 | F3: 0 | G3: 7.81 | H3: 0.43 | I3: 4.36 | J3: 0.06 | K3: 0.17 | L3: 8.6 | M3: 21.56 | N3: 11.51 | O3: 6.78 | P3: 0.83 | Q3: 1 | R3: 0.1 | S3: 6.41 | T3: 2.39 | U3: 6.04 | V3: 11.27 | W3: 4.76 | X3: 1.17 | Y3: 3.25 | Z3: 1.5 | AA3: 0
A4: 100103 | B4: HUANUCO | C4: HUANUCO | D4: CHINCHAO | E4: 4256 | F4: 0 | G4: 82.99 | H4: 0.05 | I4: 0.75 | J4: 0 | K4: 0 | L4: 1.86 | M4: 4.72 | N4: 4.11 | O4: 1.95 | P4: 0.02 | Q4: 0.02 | R4: 0 | S4: 0.21 | T4: 0.14 | U4: 1.1 | V4: 0.54 | W4: 0.4 | X4: 0.07 | Y4: 0.87 | Z4: 0.19 | AA4: 0
A5: 100104 | B5: HUANUCO | C5: HUANUCO | D5: CHURUBAMBA | E5: 4782 | F5: 0 | G5: 86.03 | H5: 0 | I5: 1.05 | J5: 0 | K5: 0.1 | L5: 1.8 | M5: 3.72 | N5: 2.28 | O5: 1.59 | P5: 0 | Q5: 0.02 | R5: 0 | S5: 0.4 | T5: 0.17 | U5: 0.52 | V5: 0.59 | W5: 0.4 | X5: 0.02 | Y5: 0.73 | Z5: 0.59 | AA5: 0
A6: 100105 | B6: HUANUCO | C6: HUANUCO | D6: MARGOS | E6: 1432 | F6: 0 | G6: 86.1 | H6: 0.07 | I6: 0.77 | J6: 0 | K6: 0 | L6: 1.82 | M6: 3.91 | N6: 0.35 | O6: 0.42 | P6: 0 | Q6: 0 | R6: 0 | S6: 0.56 | T6: 0.49 | U6: 1.61 | V6: 1.68 | W6: 1.19 | X6: 0 | Y6: 0.63 | Z6: 0.42 | AA6: 0
A7: 100106 | B7: HUANUCO | C7: HUANUCO | D7: QUISQUI | E7: 1007 | F7: 0 | G7: 86.3 | H7: 0.1 | I7: 0.2 | J7: 0 | K7: 0 | L7: 1.09 | M7: 2.48 | N7: 2.68 | O7: 1.99 | P7: 0.1 | Q7: 0 | R7: 0 | S7: 0 | T7: 0.4 | U7: 1.89 | V7: 1.59 | W7: 0.7 | X7: 0 | Y7: 0.1 | Z7: 0.4 | AA7: 0
A8: 100107 | B8: HUANUCO | C8: HUANUCO | D8: SAN FRANCISCO DE CAYRAN | E8: 1658 | F8: 0 | G8: 74.91 | H8: 0.18 | I8: 1.51 | J8: 0 | K8: 0 | L8: 2.23 | M8: 6.63 | N8: 5.67 | O8: 1.33 | P8: 0.06 | Q8: 0.12 | R8: 0 | S8: 0.72 | T8: 0.78 | U8: 0.97 | V8: 1.93 | W8: 1.93 | X8: 0.12 | Y8: 0.48 | Z8: 0.42 | AA8: 0
A9: 100108 | B9: HUANUCO | C9: HUANUCO | D9: SAN PEDRO DE CHAULAN | E9: 864 | F9: 0 | G9: 91.44 | H9: 0.12 | I9: 0.35 | J9: 0 | K9: 0 | L9: 0 | M9: 1.62 | N9: 1.04 | O9: 0.58 | P9: 0 | Q9: 0 | R9: 0 | S9: 0 | T9: 0.46 | U9: 2.43 | V9: 0.93 | W9: 0.58 | X9: 0 | Y9: 0.46 | Z9: 0 | AA9: 0
A10: 100109 | B10: HUANUCO | C10: HUANUCO | D10: SANTA MARIA DEL VALLE | E10: 6001 | F10: 0 | G10: 75.79 | H10: 0.08 | I10: 1.48 | J10: 0 | K10: 0.02 | L10: 3.28 | M10: 7.15 | N10: 4.2 | O10: 2.07 | P10: 0.1 | Q10: 0.05 | R10: 0 | S10: 0.43 | T10: 0.42 | U10: 1.63 | V10: 1.2 | W10: 0.67 | X10: 0.3 | Y10: 0.47 | Z10: 0.67 | AA10: 0
A11: 100110 | B11: HUANUCO | C11: HUANUCO | D11: YARUMAYO | E11: 410 | F11: 0 | G11: 87.56 | H11: 0 | I11: 0.73 | J11: 0 | K11: 0 | L11: 0.24 | M11: 4.63 | N11: 1.71 | O11: 0.98 | P11: 0 | Q11: 0 | R11: 0 | S11: 0.24 | T11: 0.24 | U11: 0.49 | V11: 1.22 | W11: 0.98 | X11: 0 | Y11: 0.24 | Z11: 0.73 | AA11: 0
A12: 100111 | B12: HUANUCO | C12: HUANUCO | D12: PILLCO MARCA | E12: 16879 | F12: 0 | G12: 6.38 | H12: 1.03 | I12: 11.43 | J12: 0.06 | K12: 0.17 | L12: 9.25 | M12: 18.1 | N12: 11.11 | O12: 6.08 | P12: 0.88 | Q12: 0.82 | R12: 0.04 | S12: 5.89 | T12: 2.11 | U12: 5.8 | V12: 11.81 | W12: 4.06 | X12: 0.73 | Y12: 2.91 | Z12: 1.32 | AA12: 0
A13: 100112 | B13: HUANUCO | C13: HUANUCO | D13: YACUS | E13: 2129 | F13: 0 | G13: 91.69 | H13: 0 | I13: 0.56 | J13: 0 | K13: 0 | L13: 1.08 | M13: 2.4 | N13: 0.38 | O13: 1.27 | P13: 0 | Q13: 0 | R13: 0 | S13: 0.7 | T13: 0 | U13: 0.09 | V13: 0.61 | W13: 0.38 | X13: 0.09 | Y13: 0.66 | Z13: 0.09 | AA13: 0
... A510: 150904 | B510: LIMA | C510: OYON | D510: COCHAMARCA | E510: 418 | F510: 0 | G510: 91.87 | H510: 0 | I510: 0.24 | J510: 0 | K510: 0 | L510: 2.15 | M510: 1.44 | N510: 0.72 | O510: 0 | P510: 0 | Q510: 0 | R510: 0 | S510: 0.24 | T510: 0 | U510: 1.2 | V510: 1.2 | W510: 0.24 | X510: 0 | Y510: 0.48 | Z510: 0.24 | AA510: 0
A511: 150905 | B511: LIMA | C511: OYON | E511: 0 | F511: 0 | G511: 56.35 | H511: 0 | I511: 2.85 | J511: 0 | K511: 0 | L511: 8.7 | M511: 10.36 | N511: 3.73 | O511: 4.88 | P511: 0.22 | Q511: 0 | R511: 0 | S511: 1.66 | T511: 1.66 | U511: 4.04 | V511: 3.14 | W511: 0.88 | X511: 0.22 | Y511: 1.06 | Z511: 0.26 | AA511: 0
A512: 150906 | B512: LIMA | C512: OYON | D512: PACHANGARA | E512: 1109 | F512: 0 | G512: 28.67 | H512: 0.27 | I512: 2.61 | J512: 0.45 | K512: 0 | L512: 12.89 | M512: 15.15 | N512: 9.47 | O512: 15.24 | P512: 0.27 | Q512: 0.18 | R512: 0 | S512: 3.79 | T512: 2.16 | U512: 2.71 | V512: 2.8 | W512: 0.81 | X512: 0.54 | Y512: 1.26 | Z512: 0.72 | AA512: 0
A513: 151001 | B513: LIMA | C513: YAUYOS | D513: YAUYOS | E513: 779 | F513: 0 | G513: 52.63 | H513: 0.64 | I513: 1.03 | J513: 0.39 | K513: 0 | L513: 4.36 | M513: 9.88 | N513: 1.8 | O513: 3.72 | P513: 0.13 | Q513: 0.13 | R513: 0 | S513: 3.59 | T513: 2.05 | U513: 7.83 | V513: 8.86 | W513: 2.05 | X513: 0.13 | Y513: 0.39 | Z513: 0.39 | AA513: 0
A514: 151002 | B514: LIMA | C514: YAUYOS | D514: ALIS | E514: 1393 | F514: 0 | G514: 4.16 | H514: 76.81 | I514: 2.37 | J514: 0.07 | K514: 0 | L514: 1.08 | M514: 1.94 | N514: 0.72 | O514: 3.59 | P514: 0.07 | Q514: 0 | R514: 0 | S514: 1.01 | T514: 2.44 | U514: 1.08 | V514: 1.79 | W514: 2.44 | X514: 0 | Y514: 0.43 | Z514: 0 | AA514: 0
A515: 151003 | B515: LIMA | C515: YAUYOS | D515: AYAUCA | E515: 0 | F515: 0 | G515: 76.5 | H515: 0 | I515: 1.21 | J515: 0 | K515: 0 | L515: 3.19 | M515: 6.09 | N515: 1.87 | O515: 1.3 | P515: 0 | Q515: 0 | R515: 0 | S515: 0.87 | T515: 0 | U515: 3.04 | V515: 5.22 | W515: 0.71 | X515: 0 | Y515: 0 | Z515: 0 | AA515: 0
A516: 151004 | B516: LIMA | C516: YAUYOS | D516: AYAVIRI | E516: 296 | F516: 0 | G516: 72.3 | H516: 0.34 | I516: 1.01 | J516: 0 | K516: 0 | L516: 4.73 | M516: 4.39 | N516: 1.69 | O516: 3.04 | P516: 0 | Q516: 0 | R516: 0 | S516: 2.03 | T516: 0 | U516: 2.7 | V516: 6.42 | W516: 1.35 | X516: 0 | Y516: 0 | Z516: 0 | AA516: 0
A517: 151005 | B517: LIMA | C517: YAUYOS | D517: AZANGARO | E517: 228 | F517: 0 | G517: 81.58 | H517: 0 | I517: 0.88 | J517: 0 | K517: 0 | L517: 4.39 | M517: 2.63 | N517: 2.19 | O517: 0 | P517: 0 | Q517: 0 | R517: 0 | S517: 0.88 | T517: 0 | U517: 3.95 | V517: 3.07 | W517: 0.44 | X517: 0 | Y517: 0 | Z517: 0 | AA517: 0
A518: 151006 | B518: LIMA | C518: YAUYOS | D518: CACRA | E518: 239 | F518: 0 | G518: 79.5 | H518: 0 | I518: 0.84 | J518: 0 | K518: 0 | L518: 0.42 | M518: 8.37 | N518: 2.09 | O518: 0 | P518: 0 | Q518: 0 | R518: 0 | S518: 0.84 | T518: 0 | U518: 1.26 | V518: 5.02 | W518: 0.42 | X518: 0 | Y518: 1.26 | Z518: 0 | AA518: 0
A519: 151007 | B519: LIMA | C519: YAUYOS | D519: CARANIA | E519: 71 | F519: 0 | G519: 80.28 | H519: 0 | I519: 0 | J519: 1.41 | K519: 0 | L519: 1.41 | M519: 2.82 | N519: 1.41 | O519: 1.41 | P519: 0 | Q519: 0 | R519: 0 | S519: 1.41 | T519: 0 | U519: 4.23 | V519: 2.82 | W519: 1.41 | X519: 0 | Y519: 1.41 | Z519: 0 | AA519: 0
A520: 151008 | B520: LIMA | C520: YAUYOS | D520: CATAHUASI | E520: 513 | F520: 0 | G520: 64.52 | H520: 0.39 | I520: 1.75 | J520: 0 | K520: 0 | L520: 4.09 | M520: 7.21 | N520: 2.73 | O520: 2.73 | P520: 0 | Q520: 0.19 | R520: 0 | S520: 1.17 | T520: 1.56 | U520: 2.92 | V520: 9.16 | W520: 0.97 | X520: 0 | Y520: 0.19 | Z520: 0.39 | AA520: 0
A521: 151009 | B521: LIMA | C521: YAUYOS | D521: CHOCOS | E521: 293 | F521: 0 | G521: 87.37 | H521: 0 | I521: 0 | J521: 0 | K521: 0 | L521: 0.34 | M521: 1.71 | N521: 0.68 | O521: 0.68 | P521: 0 | Q521: 0 | R521: 0 | S521: 0 | T521: 0.34 | U521: 2.73 | V521: 5.46 | W521: 0.68 | X521: 0 | Y521: 0 | Z521: 0 | AA521: 0
A522: 151010 | B522: LIMA | C522: YAUYOS | D522: COCHAS | E522: 115 | F522: 0 | G522: 60.87 | H522: 0 | I522: 1.74 | J522: 0 | K522: 0 | L522: 10.43 | M522: 14.78 | N522: 1.74 | O522: 0.87 | P522: 0 | Q522: 0 | R522: 0 | S522: 0 | T522: 0 | U522: 5.22 | V522: 2.61 | W522: 0 | X522: 0 | Y522: 0 | Z522: 1.74 | AA522: 0
A523: 151011 | B523: LIMA | C523: YAUYOS | D523: COLONIA | E523: 483 | F523: 0 | G523: 89.65 | H523: 0 | I523: 0.41 | J523: 0 | K523: 0 | L523: 0.62 | M523: 1.24 | N523: 1.45 | O523: 0.41 | P523: 0 | Q523: 0 | R523: 0 | S523: 0 | T523: 0 | U523: 2.07 | V523: 3.93 | W523: 0 | X523: 0 | Y523: 0.21 | Z523: 0 | AA523: 0
... A551: 160106 | B551: LORETO | C551: MAYNAS | D551: MAZAN | E551: 4419 | F551: 0 | G551: 79 | H551: 0 | I551: 1.97 | J551: 0 | K551: 0.05 | L551: 1.15 | M551: 7.81 | N551: 2.44 | O551: 2.51 | P551: 0.02 | Q551: 0.05 | R551: 0 | S551: 0.38 | T551: 0.32 | U551: 0.91 | V551: 1 | W551: 0.86 | X551: 0.02 | Y551: 1 | Z551: 0.52 | AA551: 0
A552: 160107 | B552: LORETO | C552: MAYNAS | E552: 0 | F552: 0 | G552: 67.66 | H552: 0.17 | I552: 2.22 | J552: 0.08 | K552: 0.14 | L552: 2.58 | M552: 7.59 | N552: 3.31 | O552: 3.22 | P552: 0.11 | Q552: 0.04 | R552: 0 | S552: 0.97 | T552: 0.95 | U552: 3.14 | V552: 4.69 | W552: 1.64 | X552: 0.09 | Y552: 0.92 | Z552: 0.48 | AA552: 0
A553: 160108 | B553: LORETO | C553: MAYNAS | D553: PUNCHANA | E553: 26516 | F553: 0 | G553: 9.12 | H553: 0.21 | I553: 8.18 | J553: 0.09 | K553: 0.17 | L553: 7.26 | M553: 24.07 | N553: 13.7 | O553: 9.1 | P553: 0.45 | Q553: 0.85 | R553: 0.06 | S553: 4.82 | T553: 3.22 | U553: 4.42 | V553: 5.45 | W553: 2.84 | X553: 0.7 | Y553: 3.62 | Z553: 1.69 | AA553: 0
A554: 160110 | B554: LORETO | C554: MAYNAS | D554: TORRES CAUSANA | E554: 1707 | F554: 0 | G554: 82.95 | H554: 0 | I554: 0.35 | J554: 0 | K554: 0.06 | L554: 0.59 | M554: 2.28 | N554: 0.82 | O554: 1 | P554: 0.12 | Q554: 0 | R554: 0 | S554: 0.06 | T554: 0.06 | U554: 5.57 | V554: 5.51 | W554: 0.29 | X554: 0 | Y554: 0.23 | Z554: 0.12 | AA554: 0
A555: 160112 | B555: LORETO | C555: MAYNAS | D555: BELEN | E555: 24332 | F555: 0 | G555: 11.11 | H555: 0.18 | I555: 7.57 | J555: 0.07 | K555: 0.19 | L555: 7.2 | M555: 30.87 | N555: 9.93 | O555: 7.69 | P555: 0.43 | Q555: 0.67 | R555: 0.07 | S555: 4.39 | T555: 2.89 | U555: 3.39 | V555: 5.07 | W555: 2.02 | X555: 0.73 | Y555: 4.04 | Z555: 1.49 | AA555: 0
A556: 160113 | B556: LORETO | C556: MAYNAS | D556: SAN JUAN BAUTISTA | E556: 44558 | F556: 0 | G556: 10.21 | H556: 0.19 | I556: 6.68 | J556: 0.09 | K556: 0.29 | L556: 8.86 | M556: 25.68 | N556: 12.32 | O556: 8.63 | P556: 0.48 | Q556: 0.62 | R556: 0.09 | S556: 4.56 | T556: 3.32 | U556: 3.56 | V556: 5.58 | W556: 2.34 | X556: 0.65 | Y556: 4.02 | Z556: 1.85 | AA556: 0
A557: 160201 | B557: LORETO | C557: ALTO AMAZONAS | D557: YURIMAGUAS | E557: 30393 | F557: 0 | G557: 31.2 | H557: 0.13 | I557: 4.78 | J557: 0.07 | K557: 0.17 | L557: 6.44 | M557: 19.03 | N557: 9.41 | O557: 5.82 | P557: 0.51 | Q557: 0.48 | R557: 0.08 | S557: 3.9 | T557: 1.76 | U557: 3.09 | V557: 6.11 | W557: 2.21 | X557: 0.42 | Y557: 3.01 | Z557: 1.39 | AA557: 0
A558: 160202 | B558: LORETO | C558: ALTO AMAZONAS | D558: BALSAPUERTO | E558: 3614 | F558: 0 | G558: 87.41 | H558: 0.03 | I558: 1.13 | J558: 0.06 | K558: 0 | L558: 1.66 | M558: 1.3 | N558: 0.28 | O558: 0.83 | P558: 0 | Q558: 0 | R558: 0 | S558: 0.42 | T558: 0.17 | U558: 0.33 | V558: 5.12 | W558: 0.77 | X558: 0 | Y558: 0.22 | Z558: 0.28 | AA558: 0
A559: 160205 | B559: LORETO | C559: ALTO AMAZONAS | D559: JEBEROS | E559: 1032 | F559: 0 | G559: 77.52 | H559: 0 | I559: 0.97 | J559: 0 | K559: 0.1 | L559: 0.68 | M559: 4.65 | N559: 0.97 | O559: 1.07 | P559: 0 | Q559: 0 | R559: 0 | S559: 1.45 | T559: 0.68 | U559: 1.07 | V559: 7.17 | W559: 2.03 | X559: 0 | Y559: 0.58 | Z559: 1.07 | AA559: 0
A560: 160206 | B560: LORETO | C560: ALTO AMAZONAS | D560: LAGUNAS | E560: 3069 | F560: 0 | G560: 62.01 | H560: 0 | I560: 2.9 | J560: 0 | K560: 0.03 | L560: 4.86 | M560: 9.61 | N560: 2.61 | O560: 2.83 | P560: 0.07 | Q560: 0.1 | R560: 0 | S560: 1.01 | T560: 1.47 | U560: 1.47 | V560: 7.4 | W560: 1.86 | X560: 0.07 | Y560: 0.91 | Z560: 0.81 | AA560: 0
A561: 160210 | B561: LORETO | C561: ALTO AMAZONAS | D561: SANTA CRUZ | E561: 1156 | F561: 0 | G561: 87.46 | H561: 0.09 | I561: 0.69 | J561: 0 | K561: 0 | L561: 0.43 | M561: 3.46 | N561: 0.35 | O561: 1.04 | P561: 0.26 | Q561: 0 | R561: 0 | S561: 0.52 | T561: 0 | U561: 1.56 | V561: 2.68 | W561: 0.95 | X561: 0 | Y561: 0.35 | Z561: 0.17 | AA561: 0
A562: 160211 | B562: LORETO | C562: ALTO AMAZONAS | D562: TENIENTE CESAR LOPEZ ROJAS | E562: 1979 | F562: 0 | G562: 86.41 | H562: 0 | I562: 0.96 | J562: 0 | K562: 0 | L562: 0.3 | M562: 4.6 | N562: 0.61 | O562: 1.11 | P562: 0.05 | Q562: 0 | R562: 0 | S562: 0.45 | T562: 0.66 | U562: 1.11 | V562: 1.11 | W562: 1.16 | X562: 0 | Y562: 1.01 | Z562: 0.45 | AA562: 0
A563: 160301 | B563: LORETO | C563: LORETO | E563: 0 | F563: 0 | G563: 67.87 | H563: 0.1 | I563: 2.02 | J563: 0.05 | K563: 0.05 | L563: 4.86 | M563: 6.69 | N563: 0.95 | O563: 3.68 | P563: 0.05 | Q563: 0 | R563: 0 | S563: 1.11 | T563: 0.8 | U563: 2.45 | V563: 6.23 | W563: 0.93 | X563: 0.05 | Y563: 1.65 | Z563: 0.45 | AA563: 0
...

Sheet Score s
A1: ubigeo | B1: distrito | C1: % Agropecuario | D1: % Pesca | E1: % Mineria | F1: % Manufactura | G1: % Electricidad y agua | H1: % Construccion | I1: % Comercio | J1: % Servicios | K1: suma % | L1: s (estres) | M1: PEA ocup. | N1: s FINAL (sin dato=peor) | O1: dato
A2: 100101 | B2: HUANUCO | C2: ='Empleo Censo'!G2-'Empleo Censo'!F2 | D2: ='Empleo Censo'!F2 | E2: ='Empleo Censo'!H2 | F2: ='Empleo Censo'!I2 | G2: ='Empleo Censo'!J2+'Empleo Censo'!K2 | H2: ='Empleo Censo'!L2 | I2: ='Empleo Censo'!M2 | J2: =SUM('Empleo Censo'!N2:AA2) | K2: =SUM(C2:J2) | L2: =SUMPRODUCT(C2:J2,Factores!$B$3:$I$3) | M2: ='Empleo Censo'!E2 | N2: =IF(M2>0,L2,Factores!$B$7) | O2: =IF(M2>0,"OK","sin PEA -> peor")
A3: 100102 | B3: AMARILIS | C3: ='Empleo Censo'!G3-'Empleo Censo'!F3 | D3: ='Empleo Censo'!F3 | E3: ='Empleo Censo'!H3 | F3: ='Empleo Censo'!I3 | G3: ='Empleo Censo'!J3+'Empleo Censo'!K3 | H3: ='Empleo Censo'!L3 | I3: ='Empleo Censo'!M3 | J3: =SUM('Empleo Censo'!N3:AA3) | K3: =SUM(C3:J3) | L3: =SUMPRODUCT(C3:J3,Factores!$B$3:$I$3) | M3: ='Empleo Censo'!E3 | N3: =IF(M3>0,L3,Factores!$B$7) | O3: =IF(M3>0,"OK","sin PEA -> peor")
A4: 100103 | B4: CHINCHAO | C4: ='Empleo Censo'!G4-'Empleo Censo'!F4 | D4: ='Empleo Censo'!F4 | E4: ='Empleo Censo'!H4 | F4: ='Empleo Censo'!I4 | G4: ='Empleo Censo'!J4+'Empleo Censo'!K4 | H4: ='Empleo Censo'!L4 | I4: ='Empleo Censo'!M4 | J4: =SUM('Empleo Censo'!N4:AA4) | K4: =SUM(C4:J4) | L4: =SUMPRODUCT(C4:J4,Factores!$B$3:$I$3) | M4: ='Empleo Censo'!E4 | N4: =IF(M4>0,L4,Factores!$B$7) | O4: =IF(M4>0,"OK","sin PEA -> peor")
A5: 100104 | B5: CHURUBAMBA | C5: ='Empleo Censo'!G5-'Empleo Censo'!F5 | D5: ='Empleo Censo'!F5 | E5: ='Empleo Censo'!H5 | F5: ='Empleo Censo'!I5 | G5: ='Empleo Censo'!J5+'Empleo Censo'!K5 | H5: ='Empleo Censo'!L5 | I5: ='Empleo Censo'!M5 | J5: =SUM('Empleo Censo'!N5:AA5) | K5: =SUM(C5:J5) | L5: =SUMPRODUCT(C5:J5,Factores!$B$3:$I$3) | M5: ='Empleo Censo'!E5 | N5: =IF(M5>0,L5,Factores!$B$7) | O5: =IF(M5>0,"OK","sin PEA -> peor")
A6: 100105 | B6: MARGOS | C6: ='Empleo Censo'!G6-'Empleo Censo'!F6 | D6: ='Empleo Censo'!F6 | E6: ='Empleo Censo'!H6 | F6: ='Empleo Censo'!I6 | G6: ='Empleo Censo'!J6+'Empleo Censo'!K6 | H6: ='Empleo Censo'!L6 | I6: ='Empleo Censo'!M6 | J6: =SUM('Empleo Censo'!N6:AA6) | K6: =SUM(C6:J6) | L6: =SUMPRODUCT(C6:J6,Factores!$B$3:$I$3) | M6: ='Empleo Censo'!E6 | N6: =IF(M6>0,L6,Factores!$B$7) | O6: =IF(M6>0,"OK","sin PEA -> peor")
A7: 100106 | B7: QUISQUI | C7: ='Empleo Censo'!G7-'Empleo Censo'!F7 | D7: ='Empleo Censo'!F7 | E7: ='Empleo Censo'!H7 | F7: ='Empleo Censo'!I7 | G7: ='Empleo Censo'!J7+'Empleo Censo'!K7 | H7: ='Empleo Censo'!L7 | I7: ='Empleo Censo'!M7 | J7: =SUM('Empleo Censo'!N7:AA7) | K7: =SUM(C7:J7) | L7: =SUMPRODUCT(C7:J7,Factores!$B$3:$I$3) | M7: ='Empleo Censo'!E7 | N7: =IF(M7>0,L7,Factores!$B$7) | O7: =IF(M7>0,"OK","sin PEA -> peor")
A8: 100107 | B8: SAN FRANCISCO DE CAYRAN | C8: ='Empleo Censo'!G8-'Empleo Censo'!F8 | D8: ='Empleo Censo'!F8 | E8: ='Empleo Censo'!H8 | F8: ='Empleo Censo'!I8 | G8: ='Empleo Censo'!J8+'Empleo Censo'!K8 | H8: ='Empleo Censo'!L8 | I8: ='Empleo Censo'!M8 | J8: =SUM('Empleo Censo'!N8:AA8) | K8: =SUM(C8:J8) | L8: =SUMPRODUCT(C8:J8,Factores!$B$3:$I$3) | M8: ='Empleo Censo'!E8 | N8: =IF(M8>0,L8,Factores!$B$7) | O8: =IF(M8>0,"OK","sin PEA -> peor")
A9: 100108 | B9: SAN PEDRO DE CHAULAN | C9: ='Empleo Censo'!G9-'Empleo Censo'!F9 | D9: ='Empleo Censo'!F9 | E9: ='Empleo Censo'!H9 | F9: ='Empleo Censo'!I9 | G9: ='Empleo Censo'!J9+'Empleo Censo'!K9 | H9: ='Empleo Censo'!L9 | I9: ='Empleo Censo'!M9 | J9: =SUM('Empleo Censo'!N9:AA9) | K9: =SUM(C9:J9) | L9: =SUMPRODUCT(C9:J9,Factores!$B$3:$I$3) | M9: ='Empleo Censo'!E9 | N9: =IF(M9>0,L9,Factores!$B$7) | O9: =IF(M9>0,"OK","sin PEA -> peor")
A10: 100109 | B10: SANTA MARIA DEL VALLE | C10: ='Empleo Censo'!G10-'Empleo Censo'!F10 | D10: ='Empleo Censo'!F10 | E10: ='Empleo Censo'!H10 | F10: ='Empleo Censo'!I10 | G10: ='Empleo Censo'!J10+'Empleo Censo'!K10 | H10: ='Empleo Censo'!L10 | I10: ='Empleo Censo'!M10 | J10: =SUM('Empleo Censo'!N10:AA10) | K10: =SUM(C10:J10) | L10: =SUMPRODUCT(C10:J10,Factores!$B$3:$I$3) | M10: ='Empleo Censo'!E10 | N10: =IF(M10>0,L10,Factores!$B$7) | O10: =IF(M10>0,"OK","sin PEA -> peor")
A11: 100110 | B11: YARUMAYO | C11: ='Empleo Censo'!G11-'Empleo Censo'!F11 | D11: ='Empleo Censo'!F11 | E11: ='Empleo Censo'!H11 | F11: ='Empleo Censo'!I11 | G11: ='Empleo Censo'!J11+'Empleo Censo'!K11 | H11: ='Empleo Censo'!L11 | I11: ='Empleo Censo'!M11 | J11: =SUM('Empleo Censo'!N11:AA11) | K11: =SUM(C11:J11) | L11: =SUMPRODUCT(C11:J11,Factores!$B$3:$I$3) | M11: ='Empleo Censo'!E11 | N11: =IF(M11>0,L11,Factores!$B$7) | O11: =IF(M11>0,"OK","sin PEA -> peor")
A12: 100111 | B12: PILLCO MARCA | C12: ='Empleo Censo'!G12-'Empleo Censo'!F12 | D12: ='Empleo Censo'!F12 | E12: ='Empleo Censo'!H12 | F12: ='Empleo Censo'!I12 | G12: ='Empleo Censo'!J12+'Empleo Censo'!K12 | H12: ='Empleo Censo'!L12 | I12: ='Empleo Censo'!M12 | J12: =SUM('Empleo Censo'!N12:AA12) | K12: =SUM(C12:J12) | L12: =SUMPRODUCT(C12:J12,Factores!$B$3:$I$3) | M12: ='Empleo Censo'!E12 | N12: =IF(M12>0,L12,Factores!$B$7) | O12: =IF(M12>0,"OK","sin PEA -> peor")
A13: 100112 | B13: YACUS | C13: ='Empleo Censo'!G13-'Empleo Censo'!F13 | D13: ='Empleo Censo'!F13 | E13: ='Empleo Censo'!H13 | F13: ='Empleo Censo'!I13 | G13: ='Empleo Censo'!J13+'Empleo Censo'!K13 | H13: ='Empleo Censo'!L13 | I13: ='Empleo Censo'!M13 | J13: =SUM('Empleo Censo'!N13:AA13) | K13: =SUM(C13:J13) | L13: =SUMPRODUCT(C13:J13,Factores!$B$3:$I$3) | M13: ='Empleo Censo'!E13 | N13: =IF(M13>0,L13,Factores!$B$7) | O13: =IF(M13>0,"OK","sin PEA -> peor")
... A510: 150904 | B510: COCHAMARCA | C510: ='Empleo Censo'!G510-'Empleo Censo'!F510 | D510: ='Empleo Censo'!F510 | E510: ='Empleo Censo'!H510 | F510: ='Empleo Censo'!I510 | G510: ='Empleo Censo'!J510+'Empleo Censo'!K510 | H510: ='Empleo Censo'!L510 | I510: ='Empleo Censo'!M510 | J510: =SUM('Empleo Censo'!N510:AA510) | K510: =SUM(C510:J510) | L510: =SUMPRODUCT(C510:J510,Factores!$B$3:$I$3) | M510: ='Empleo Censo'!E510 | N510: =IF(M510>0,L510,Factores!$B$7) | O510: =IF(M510>0,"OK","sin PEA -> peor")
A511: 150905 | C511: ='Empleo Censo'!G511-'Empleo Censo'!F511 | D511: ='Empleo Censo'!F511 | E511: ='Empleo Censo'!H511 | F511: ='Empleo Censo'!I511 | G511: ='Empleo Censo'!J511+'Empleo Censo'!K511 | H511: ='Empleo Censo'!L511 | I511: ='Empleo Censo'!M511 | J511: =SUM('Empleo Censo'!N511:AA511) | K511: =SUM(C511:J511) | L511: =SUMPRODUCT(C511:J511,Factores!$B$3:$I$3) | M511: ='Empleo Censo'!E511 | N511: =IF(M511>0,L511,Factores!$B$7) | O511: =IF(M511>0,"OK","sin PEA -> peor")
A512: 150906 | B512: PACHANGARA | C512: ='Empleo Censo'!G512-'Empleo Censo'!F512 | D512: ='Empleo Censo'!F512 | E512: ='Empleo Censo'!H512 | F512: ='Empleo Censo'!I512 | G512: ='Empleo Censo'!J512+'Empleo Censo'!K512 | H512: ='Empleo Censo'!L512 | I512: ='Empleo Censo'!M512 | J512: =SUM('Empleo Censo'!N512:AA512) | K512: =SUM(C512:J512) | L512: =SUMPRODUCT(C512:J512,Factores!$B$3:$I$3) | M512: ='Empleo Censo'!E512 | N512: =IF(M512>0,L512,Factores!$B$7) | O512: =IF(M512>0,"OK","sin PEA -> peor")
A513: 151001 | B513: YAUYOS | C513: ='Empleo Censo'!G513-'Empleo Censo'!F513 | D513: ='Empleo Censo'!F513 | E513: ='Empleo Censo'!H513 | F513: ='Empleo Censo'!I513 | G513: ='Empleo Censo'!J513+'Empleo Censo'!K513 | H513: ='Empleo Censo'!L513 | I513: ='Empleo Censo'!M513 | J513: =SUM('Empleo Censo'!N513:AA513) | K513: =SUM(C513:J513) | L513: =SUMPRODUCT(C513:J513,Factores!$B$3:$I$3) | M513: ='Empleo Censo'!E513 | N513: =IF(M513>0,L513,Factores!$B$7) | O513: =IF(M513>0,"OK","sin PEA -> peor")
A514: 151002 | B514: ALIS | C514: ='Empleo Censo'!G514-'Empleo Censo'!F514 | D514: ='Empleo Censo'!F514 | E514: ='Empleo Censo'!H514 | F514: ='Empleo Censo'!I514 | G514: ='Empleo Censo'!J514+'Empleo Censo'!K514 | H514: ='Empleo Censo'!L514 | I514: ='Empleo Censo'!M514 | J514: =SUM('Empleo Censo'!N514:AA514) | K514: =SUM(C514:J514) | L514: =SUMPRODUCT(C514:J514,Factores!$B$3:$I$3) | M514: ='Empleo Censo'!E514 | N514: =IF(M514>0,L514,Factores!$B$7) | O514: =IF(M514>0,"OK","sin PEA -> peor")
A515: 151003 | B515: AYAUCA | C515: ='Empleo Censo'!G515-'Empleo Censo'!F515 | D515: ='Empleo Censo'!F515 | E515: ='Empleo Censo'!H515 | F515: ='Empleo Censo'!I515 | G515: ='Empleo Censo'!J515+'Empleo Censo'!K515 | H515: ='Empleo Censo'!L515 | I515: ='Empleo Censo'!M515 | J515: =SUM('Empleo Censo'!N515:AA515) | K515: =SUM(C515:J515) | L515: =SUMPRODUCT(C515:J515,Factores!$B$3:$I$3) | M515: ='Empleo Censo'!E515 | N515: =IF(M515>0,L515,Factores!$B$7) | O515: =IF(M515>0,"OK","sin PEA -> peor")
A516: 151004 | B516: AYAVIRI | C516: ='Empleo Censo'!G516-'Empleo Censo'!F516 | D516: ='Empleo Censo'!F516 | E516: ='Empleo Censo'!H516 | F516: ='Empleo Censo'!I516 | G516: ='Empleo Censo'!J516+'Empleo Censo'!K516 | H516: ='Empleo Censo'!L516 | I516: ='Empleo Censo'!M516 | J516: =SUM('Empleo Censo'!N516:AA516) | K516: =SUM(C516:J516) | L516: =SUMPRODUCT(C516:J516,Factores!$B$3:$I$3) | M516: ='Empleo Censo'!E516 | N516: =IF(M516>0,L516,Factores!$B$7) | O516: =IF(M516>0,"OK","sin PEA -> peor")
A517: 151005 | B517: AZANGARO | C517: ='Empleo Censo'!G517-'Empleo Censo'!F517 | D517: ='Empleo Censo'!F517 | E517: ='Empleo Censo'!H517 | F517: ='Empleo Censo'!I517 | G517: ='Empleo Censo'!J517+'Empleo Censo'!K517 | H517: ='Empleo Censo'!L517 | I517: ='Empleo Censo'!M517 | J517: =SUM('Empleo Censo'!N517:AA517) | K517: =SUM(C517:J517) | L517: =SUMPRODUCT(C517:J517,Factores!$B$3:$I$3) | M517: ='Empleo Censo'!E517 | N517: =IF(M517>0,L517,Factores!$B$7) | O517: =IF(M517>0,"OK","sin PEA -> peor")
A518: 151006 | B518: CACRA | C518: ='Empleo Censo'!G518-'Empleo Censo'!F518 | D518: ='Empleo Censo'!F518 | E518: ='Empleo Censo'!H518 | F518: ='Empleo Censo'!I518 | G518: ='Empleo Censo'!J518+'Empleo Censo'!K518 | H518: ='Empleo Censo'!L518 | I518: ='Empleo Censo'!M518 | J518: =SUM('Empleo Censo'!N518:AA518) | K518: =SUM(C518:J518) | L518: =SUMPRODUCT(C518:J518,Factores!$B$3:$I$3) | M518: ='Empleo Censo'!E518 | N518: =IF(M518>0,L518,Factores!$B$7) | O518: =IF(M518>0,"OK","sin PEA -> peor")
A519: 151007 | B519: CARANIA | C519: ='Empleo Censo'!G519-'Empleo Censo'!F519 | D519: ='Empleo Censo'!F519 | E519: ='Empleo Censo'!H519 | F519: ='Empleo Censo'!I519 | G519: ='Empleo Censo'!J519+'Empleo Censo'!K519 | H519: ='Empleo Censo'!L519 | I519: ='Empleo Censo'!M519 | J519: =SUM('Empleo Censo'!N519:AA519) | K519: =SUM(C519:J519) | L519: =SUMPRODUCT(C519:J519,Factores!$B$3:$I$3) | M519: ='Empleo Censo'!E519 | N519: =IF(M519>0,L519,Factores!$B$7) | O519: =IF(M519>0,"OK","sin PEA -> peor")
A520: 151008 | B520: CATAHUASI | C520: ='Empleo Censo'!G520-'Empleo Censo'!F520 | D520: ='Empleo Censo'!F520 | E520: ='Empleo Censo'!H520 | F520: ='Empleo Censo'!I520 | G520: ='Empleo Censo'!J520+'Empleo Censo'!K520 | H520: ='Empleo Censo'!L520 | I520: ='Empleo Censo'!M520 | J520: =SUM('Empleo Censo'!N520:AA520) | K520: =SUM(C520:J520) | L520: =SUMPRODUCT(C520:J520,Factores!$B$3:$I$3) | M520: ='Empleo Censo'!E520 | N520: =IF(M520>0,L520,Factores!$B$7) | O520: =IF(M520>0,"OK","sin PEA -> peor")
A521: 151009 | B521: CHOCOS | C521: ='Empleo Censo'!G521-'Empleo Censo'!F521 | D521: ='Empleo Censo'!F521 | E521: ='Empleo Censo'!H521 | F521: ='Empleo Censo'!I521 | G521: ='Empleo Censo'!J521+'Empleo Censo'!K521 | H521: ='Empleo Censo'!L521 | I521: ='Empleo Censo'!M521 | J521: =SUM('Empleo Censo'!N521:AA521) | K521: =SUM(C521:J521) | L521: =SUMPRODUCT(C521:J521,Factores!$B$3:$I$3) | M521: ='Empleo Censo'!E521 | N521: =IF(M521>0,L521,Factores!$B$7) | O521: =IF(M521>0,"OK","sin PEA -> peor")
A522: 151010 | B522: COCHAS | C522: ='Empleo Censo'!G522-'Empleo Censo'!F522 | D522: ='Empleo Censo'!F522 | E522: ='Empleo Censo'!H522 | F522: ='Empleo Censo'!I522 | G522: ='Empleo Censo'!J522+'Empleo Censo'!K522 | H522: ='Empleo Censo'!L522 | I522: ='Empleo Censo'!M522 | J522: =SUM('Empleo Censo'!N522:AA522) | K522: =SUM(C522:J522) | L522: =SUMPRODUCT(C522:J522,Factores!$B$3:$I$3) | M522: ='Empleo Censo'!E522 | N522: =IF(M522>0,L522,Factores!$B$7) | O522: =IF(M522>0,"OK","sin PEA -> peor")
A523: 151011 | B523: COLONIA | C523: ='Empleo Censo'!G523-'Empleo Censo'!F523 | D523: ='Empleo Censo'!F523 | E523: ='Empleo Censo'!H523 | F523: ='Empleo Censo'!I523 | G523: ='Empleo Censo'!J523+'Empleo Censo'!K523 | H523: ='Empleo Censo'!L523 | I523: ='Empleo Censo'!M523 | J523: =SUM('Empleo Censo'!N523:AA523) | K523: =SUM(C523:J523) | L523: =SUMPRODUCT(C523:J523,Factores!$B$3:$I$3) | M523: ='Empleo Censo'!E523 | N523: =IF(M523>0,L523,Factores!$B$7) | O523: =IF(M523>0,"OK","sin PEA -> peor")
... A551: 160106 | B551: MAZAN | C551: ='Empleo Censo'!G551-'Empleo Censo'!F551 | D551: ='Empleo Censo'!F551 | E551: ='Empleo Censo'!H551 | F551: ='Empleo Censo'!I551 | G551: ='Empleo Censo'!J551+'Empleo Censo'!K551 | H551: ='Empleo Censo'!L551 | I551: ='Empleo Censo'!M551 | J551: =SUM('Empleo Censo'!N551:AA551) | K551: =SUM(C551:J551) | L551: =SUMPRODUCT(C551:J551,Factores!$B$3:$I$3) | M551: ='Empleo Censo'!E551 | N551: =IF(M551>0,L551,Factores!$B$7) | O551: =IF(M551>0,"OK","sin PEA -> peor")
A552: 160107 | C552: ='Empleo Censo'!G552-'Empleo Censo'!F552 | D552: ='Empleo Censo'!F552 | E552: ='Empleo Censo'!H552 | F552: ='Empleo Censo'!I552 | G552: ='Empleo Censo'!J552+'Empleo Censo'!K552 | H552: ='Empleo Censo'!L552 | I552: ='Empleo Censo'!M552 | J552: =SUM('Empleo Censo'!N552:AA552) | K552: =SUM(C552:J552) | L552: =SUMPRODUCT(C552:J552,Factores!$B$3:$I$3) | M552: ='Empleo Censo'!E552 | N552: =IF(M552>0,L552,Factores!$B$7) | O552: =IF(M552>0,"OK","sin PEA -> peor")
A553: 160108 | B553: PUNCHANA | C553: ='Empleo Censo'!G553-'Empleo Censo'!F553 | D553: ='Empleo Censo'!F553 | E553: ='Empleo Censo'!H553 | F553: ='Empleo Censo'!I553 | G553: ='Empleo Censo'!J553+'Empleo Censo'!K553 | H553: ='Empleo Censo'!L553 | I553: ='Empleo Censo'!M553 | J553: =SUM('Empleo Censo'!N553:AA553) | K553: =SUM(C553:J553) | L553: =SUMPRODUCT(C553:J553,Factores!$B$3:$I$3) | M553: ='Empleo Censo'!E553 | N553: =IF(M553>0,L553,Factores!$B$7) | O553: =IF(M553>0,"OK","sin PEA -> peor")
A554: 160110 | B554: TORRES CAUSANA | C554: ='Empleo Censo'!G554-'Empleo Censo'!F554 | D554: ='Empleo Censo'!F554 | E554: ='Empleo Censo'!H554 | F554: ='Empleo Censo'!I554 | G554: ='Empleo Censo'!J554+'Empleo Censo'!K554 | H554: ='Empleo Censo'!L554 | I554: ='Empleo Censo'!M554 | J554: =SUM('Empleo Censo'!N554:AA554) | K554: =SUM(C554:J554) | L554: =SUMPRODUCT(C554:J554,Factores!$B$3:$I$3) | M554: ='Empleo Censo'!E554 | N554: =IF(M554>0,L554,Factores!$B$7) | O554: =IF(M554>0,"OK","sin PEA -> peor")
A555: 160112 | B555: BELEN | C555: ='Empleo Censo'!G555-'Empleo Censo'!F555 | D555: ='Empleo Censo'!F555 | E555: ='Empleo Censo'!H555 | F555: ='Empleo Censo'!I555 | G555: ='Empleo Censo'!J555+'Empleo Censo'!K555 | H555: ='Empleo Censo'!L555 | I555: ='Empleo Censo'!M555 | J555: =SUM('Empleo Censo'!N555:AA555) | K555: =SUM(C555:J555) | L555: =SUMPRODUCT(C555:J555,Factores!$B$3:$I$3) | M555: ='Empleo Censo'!E555 | N555: =IF(M555>0,L555,Factores!$B$7) | O555: =IF(M555>0,"OK","sin PEA -> peor")
A556: 160113 | B556: SAN JUAN BAUTISTA | C556: ='Empleo Censo'!G556-'Empleo Censo'!F556 | D556: ='Empleo Censo'!F556 | E556: ='Empleo Censo'!H556 | F556: ='Empleo Censo'!I556 | G556: ='Empleo Censo'!J556+'Empleo Censo'!K556 | H556: ='Empleo Censo'!L556 | I556: ='Empleo Censo'!M556 | J556: =SUM('Empleo Censo'!N556:AA556) | K556: =SUM(C556:J556) | L556: =SUMPRODUCT(C556:J556,Factores!$B$3:$I$3) | M556: ='Empleo Censo'!E556 | N556: =IF(M556>0,L556,Factores!$B$7) | O556: =IF(M556>0,"OK","sin PEA -> peor")
A557: 160201 | B557: YURIMAGUAS | C557: ='Empleo Censo'!G557-'Empleo Censo'!F557 | D557: ='Empleo Censo'!F557 | E557: ='Empleo Censo'!H557 | F557: ='Empleo Censo'!I557 | G557: ='Empleo Censo'!J557+'Empleo Censo'!K557 | H557: ='Empleo Censo'!L557 | I557: ='Empleo Censo'!M557 | J557: =SUM('Empleo Censo'!N557:AA557) | K557: =SUM(C557:J557) | L557: =SUMPRODUCT(C557:J557,Factores!$B$3:$I$3) | M557: ='Empleo Censo'!E557 | N557: =IF(M557>0,L557,Factores!$B$7) | O557: =IF(M557>0,"OK","sin PEA -> peor")
A558: 160202 | B558: BALSAPUERTO | C558: ='Empleo Censo'!G558-'Empleo Censo'!F558 | D558: ='Empleo Censo'!F558 | E558: ='Empleo Censo'!H558 | F558: ='Empleo Censo'!I558 | G558: ='Empleo Censo'!J558+'Empleo Censo'!K558 | H558: ='Empleo Censo'!L558 | I558: ='Empleo Censo'!M558 | J558: =SUM('Empleo Censo'!N558:AA558) | K558: =SUM(C558:J558) | L558: =SUMPRODUCT(C558:J558,Factores!$B$3:$I$3) | M558: ='Empleo Censo'!E558 | N558: =IF(M558>0,L558,Factores!$B$7) | O558: =IF(M558>0,"OK","sin PEA -> peor")
A559: 160205 | B559: JEBEROS | C559: ='Empleo Censo'!G559-'Empleo Censo'!F559 | D559: ='Empleo Censo'!F559 | E559: ='Empleo Censo'!H559 | F559: ='Empleo Censo'!I559 | G559: ='Empleo Censo'!J559+'Empleo Censo'!K559 | H559: ='Empleo Censo'!L559 | I559: ='Empleo Censo'!M559 | J559: =SUM('Empleo Censo'!N559:AA559) | K559: =SUM(C559:J559) | L559: =SUMPRODUCT(C559:J559,Factores!$B$3:$I$3) | M559: ='Empleo Censo'!E559 | N559: =IF(M559>0,L559,Factores!$B$7) | O559: =IF(M559>0,"OK","sin PEA -> peor")
A560: 160206 | B560: LAGUNAS | C560: ='Empleo Censo'!G560-'Empleo Censo'!F560 | D560: ='Empleo Censo'!F560 | E560: ='Empleo Censo'!H560 | F560: ='Empleo Censo'!I560 | G560: ='Empleo Censo'!J560+'Empleo Censo'!K560 | H560: ='Empleo Censo'!L560 | I560: ='Empleo Censo'!M560 | J560: =SUM('Empleo Censo'!N560:AA560) | K560: =SUM(C560:J560) | L560: =SUMPRODUCT(C560:J560,Factores!$B$3:$I$3) | M560: ='Empleo Censo'!E560 | N560: =IF(M560>0,L560,Factores!$B$7) | O560: =IF(M560>0,"OK","sin PEA -> peor")
A561: 160210 | B561: SANTA CRUZ | C561: ='Empleo Censo'!G561-'Empleo Censo'!F561 | D561: ='Empleo Censo'!F561 | E561: ='Empleo Censo'!H561 | F561: ='Empleo Censo'!I561 | G561: ='Empleo Censo'!J561+'Empleo Censo'!K561 | H561: ='Empleo Censo'!L561 | I561: ='Empleo Censo'!M561 | J561: =SUM('Empleo Censo'!N561:AA561) | K561: =SUM(C561:J561) | L561: =SUMPRODUCT(C561:J561,Factores!$B$3:$I$3) | M561: ='Empleo Censo'!E561 | N561: =IF(M561>0,L561,Factores!$B$7) | O561: =IF(M561>0,"OK","sin PEA -> peor")
A562: 160211 | B562: TENIENTE CESAR LOPEZ ROJAS | C562: ='Empleo Censo'!G562-'Empleo Censo'!F562 | D562: ='Empleo Censo'!F562 | E562: ='Empleo Censo'!H562 | F562: ='Empleo Censo'!I562 | G562: ='Empleo Censo'!J562+'Empleo Censo'!K562 | H562: ='Empleo Censo'!L562 | I562: ='Empleo Censo'!M562 | J562: =SUM('Empleo Censo'!N562:AA562) | K562: =SUM(C562:J562) | L562: =SUMPRODUCT(C562:J562,Factores!$B$3:$I$3) | M562: ='Empleo Censo'!E562 | N562: =IF(M562>0,L562,Factores!$B$7) | O562: =IF(M562>0,"OK","sin PEA -> peor")
A563: 160301 | C563: ='Empleo Censo'!G563-'Empleo Censo'!F563 | D563: ='Empleo Censo'!F563 | E563: ='Empleo Censo'!H563 | F563: ='Empleo Censo'!I563 | G563: ='Empleo Censo'!J563+'Empleo Censo'!K563 | H563: ='Empleo Censo'!L563 | I563: ='Empleo Censo'!M563 | J563: =SUM('Empleo Censo'!N563:AA563) | K563: =SUM(C563:J563) | L563: =SUMPRODUCT(C563:J563,Factores!$B$3:$I$3) | M563: ='Empleo Censo'!E563 | N563: =IF(M563>0,L563,Factores!$B$7) | O563: =IF(M563>0,"OK","sin PEA -> peor")
...
