Workbook

Sheet LEEME
A1: TCNB_calibracion_series.xlsx
A2: Series mensuales de la calibracion de PD de TC No Bancarizado.
A4: QUE HAY EN CADA HOJA
A5: IBK_general / IBK_N1 / N2 / N3 Interbank, poblacion clean, total y por nodo de politica.
A6: SSFF_con_BCP el sistema SIN Interbank: BCP, Scotiabank, BBVA y Falabella.
A7: SSFF_sin_BCP lo mismo, sacando ademas a BCP.
A8: SISTEMA_5 las cinco entidades del alcance, Interbank incluido.
A9: ENT_xxxxx cada entidad por separado.
A11: POBLACION
A12: flg_clean = 1 y pd_raw no nula, en cada entidad. Ventana 202303 a 202605.
A13: Sobre IBK la fuente es full_calibrated.parquet, la salida del propio pipeline.
A15: LA COLUMNA "PD cal NUEVA"
... A64: Generado por Programas/reportes/10_excel_series.py

Sheet RESUMEN
A1: RESUMEN
A2: Ponderado por n sobre los meses con mora 12m cerrada. Todo formula viva.
A4: poblacion | B4: n total | C4: PD sin calibrar | D4: PD cal vigente | E4: PD cal NUEVA | F4: mora 12m | G4: EC vigente | H4: EC NUEVA | I4: semaforo NUEVA | J4: n visible IBK | K4: % visible | L4: PD NUEVA visible | M4: mora 12m visible | N4: EC NUEVA visible | O4: semaforo visible
A5: IBK_general | B5: =SUMPRODUCT(ISNUMBER('IBK_general'!$O$5:$O$43)*'IBK_general'!$B$5:$B$43) | C5: =IFERROR(SUMPRODUCT(ISNUMBER('IBK_general'!$O$5:$O$43)*'IBK_general'!$B$5:$B$43*'IBK_general'!$C$5:$C$43)/SUMPRODUCT(ISNUMBER('IBK_general'!$O$5:$O$43)*'IBK_general'!$B$5:$B$43),"") | D5: =IFERROR(SUMPRODUCT(ISNUMBER('IBK_general'!$O$5:$O$43)*'IBK_general'!$B$5:$B$43*'IBK_general'!$D$5:$D$43)/SUMPRODUCT(ISNUMBER('IBK_general'!$O$5:$O$43)*'IBK_general'!$B$5:$B$43),"") | E5: =IFERROR(SUMPRODUCT(ISNUMBER('IBK_general'!$O$5:$O$43)*'IBK_general'!$B$5:$B$43*'IBK_general'!$E$5:$E$43)/SUMPRODUCT(ISNUMBER('IBK_general'!$O$5:$O$43)*'IBK_general'!$B$5:$B$43),"") | F5: =IFERROR(SUMPRODUCT(ISNUMBER('IBK_general'!$O$5:$O$43)*'IBK_general'!$B$5:$B$43*'IBK_general'!$O$5:$O$43)/SUMPRODUCT(ISNUMBER('IBK_general'!$O$5:$O$43)*'IBK_general'!$B$5:$B$43),"") | G5: =IFERROR(D5/F5-1,"") | H5: =IFERROR(E5/F5-1,"") | I5: =IF(H5="","",IF(OR(H5<-0.25,H5>0.3),"ROJO",IF(OR(H5<-0.1,H5>0.15),"AMBAR","VERDE"))) | J5: =SUMPRODUCT(ISNUMBER('IBK_general'!$AA$5:$AA$43)*'IBK_general'!$Y$5:$Y$43) | K5: =IFERROR(J5/B5,"") | L5: =IFERROR(SUMPRODUCT(ISNUMBER('IBK_general'!$AA$5:$AA$43)*'IBK_general'!$Y$5:$Y$43*'IBK_general'!$Z$5:$Z$43)/SUMPRODUCT(ISNUMBER('IBK_general'!$AA$5:$AA$43)*'IBK_general'!$Y$5:$Y$43),"") | M5: =IFERROR(SUMPRODUCT(ISNUMBER('IBK_general'!$AA$5:$AA$43)*'IBK_general'!$Y$5:$Y$43*'IBK_general'!$AA$5:$AA$43)/SUMPRODUCT(ISNUMBER('IBK_general'!$AA$5:$AA$43)*'IBK_general'!$Y$5:$Y$43),"") | N5: =IFERROR(L5/M5-1,"") | O5: =IF(N5="","",IF(OR(N5<-0.25,N5>0.3),"ROJO",IF(OR(N5<-0.1,N5>0.15),"AMBAR","VERDE")))
A6: IBK_N1 | B6: =SUMPRODUCT(ISNUMBER('IBK_N1'!$O$5:$O$43)*'IBK_N1'!$B$5:$B$43) | C6: =IFERROR(SUMPRODUCT(ISNUMBER('IBK_N1'!$O$5:$O$43)*'IBK_N1'!$B$5:$B$43*'IBK_N1'!$C$5:$C$43)/SUMPRODUCT(ISNUMBER('IBK_N1'!$O$5:$O$43)*'IBK_N1'!$B$5:$B$43),"") | D6: =IFERROR(SUMPRODUCT(ISNUMBER('IBK_N1'!$O$5:$O$43)*'IBK_N1'!$B$5:$B$43*'IBK_N1'!$D$5:$D$43)/SUMPRODUCT(ISNUMBER('IBK_N1'!$O$5:$O$43)*'IBK_N1'!$B$5:$B$43),"") | E6: =IFERROR(SUMPRODUCT(ISNUMBER('IBK_N1'!$O$5:$O$43)*'IBK_N1'!$B$5:$B$43*'IBK_N1'!$E$5:$E$43)/SUMPRODUCT(ISNUMBER('IBK_N1'!$O$5:$O$43)*'IBK_N1'!$B$5:$B$43),"") | F6: =IFERROR(SUMPRODUCT(ISNUMBER('IBK_N1'!$O$5:$O$43)*'IBK_N1'!$B$5:$B$43*'IBK_N1'!$O$5:$O$43)/SUMPRODUCT(ISNUMBER('IBK_N1'!$O$5:$O$43)*'IBK_N1'!$B$5:$B$43),"") | G6: =IFERROR(D6/F6-1,"") | H6: =IFERROR(E6/F6-1,"") | I6: =IF(H6="","",IF(OR(H6<-0.25,H6>0.3),"ROJO",IF(OR(H6<-0.1,H6>0.15),"AMBAR","VERDE"))) | J6: =SUMPRODUCT(ISNUMBER('IBK_N1'!$AA$5:$AA$43)*'IBK_N1'!$Y$5:$Y$43) | K6: =IFERROR(J6/B6,"") | L6: =IFERROR(SUMPRODUCT(ISNUMBER('IBK_N1'!$AA$5:$AA$43)*'IBK_N1'!$Y$5:$Y$43*'IBK_N1'!$Z$5:$Z$43)/SUMPRODUCT(ISNUMBER('IBK_N1'!$AA$5:$AA$43)*'IBK_N1'!$Y$5:$Y$43),"") | M6: =IFERROR(SUMPRODUCT(ISNUMBER('IBK_N1'!$AA$5:$AA$43)*'IBK_N1'!$Y$5:$Y$43*'IBK_N1'!$AA$5:$AA$43)/SUMPRODUCT(ISNUMBER('IBK_N1'!$AA$5:$AA$43)*'IBK_N1'!$Y$5:$Y$43),"") | N6: =IFERROR(L6/M6-1,"") | O6: =IF(N6="","",IF(OR(N6<-0.25,N6>0.3),"ROJO",IF(OR(N6<-0.1,N6>0.15),"AMBAR","VERDE")))
A7: IBK_N2 | B7: =SUMPRODUCT(ISNUMBER('IBK_N2'!$O$5:$O$43)*'IBK_N2'!$B$5:$B$43) | C7: =IFERROR(SUMPRODUCT(ISNUMBER('IBK_N2'!$O$5:$O$43)*'IBK_N2'!$B$5:$B$43*'IBK_N2'!$C$5:$C$43)/SUMPRODUCT(ISNUMBER('IBK_N2'!$O$5:$O$43)*'IBK_N2'!$B$5:$B$43),"") | D7: =IFERROR(SUMPRODUCT(ISNUMBER('IBK_N2'!$O$5:$O$43)*'IBK_N2'!$B$5:$B$43*'IBK_N2'!$D$5:$D$43)/SUMPRODUCT(ISNUMBER('IBK_N2'!$O$5:$O$43)*'IBK_N2'!$B$5:$B$43),"") | E7: =IFERROR(SUMPRODUCT(ISNUMBER('IBK_N2'!$O$5:$O$43)*'IBK_N2'!$B$5:$B$43*'IBK_N2'!$E$5:$E$43)/SUMPRODUCT(ISNUMBER('IBK_N2'!$O$5:$O$43)*'IBK_N2'!$B$5:$B$43),"") | F7: =IFERROR(SUMPRODUCT(ISNUMBER('IBK_N2'!$O$5:$O$43)*'IBK_N2'!$B$5:$B$43*'IBK_N2'!$O$5:$O$43)/SUMPRODUCT(ISNUMBER('IBK_N2'!$O$5:$O$43)*'IBK_N2'!$B$5:$B$43),"") | G7: =IFERROR(D7/F7-1,"") | H7: =IFERROR(E7/F7-1,"") | I7: =IF(H7="","",IF(OR(H7<-0.25,H7>0.3),"ROJO",IF(OR(H7<-0.1,H7>0.15),"AMBAR","VERDE"))) | J7: =SUMPRODUCT(ISNUMBER('IBK_N2'!$AA$5:$AA$43)*'IBK_N2'!$Y$5:$Y$43) | K7: =IFERROR(J7/B7,"") | L7: =IFERROR(SUMPRODUCT(ISNUMBER('IBK_N2'!$AA$5:$AA$43)*'IBK_N2'!$Y$5:$Y$43*'IBK_N2'!$Z$5:$Z$43)/SUMPRODUCT(ISNUMBER('IBK_N2'!$AA$5:$AA$43)*'IBK_N2'!$Y$5:$Y$43),"") | M7: =IFERROR(SUMPRODUCT(ISNUMBER('IBK_N2'!$AA$5:$AA$43)*'IBK_N2'!$Y$5:$Y$43*'IBK_N2'!$AA$5:$AA$43)/SUMPRODUCT(ISNUMBER('IBK_N2'!$AA$5:$AA$43)*'IBK_N2'!$Y$5:$Y$43),"") | N7: =IFERROR(L7/M7-1,"") | O7: =IF(N7="","",IF(OR(N7<-0.25,N7>0.3),"ROJO",IF(OR(N7<-0.1,N7>0.15),"AMBAR","VERDE")))
A8: IBK_N3 | B8: =SUMPRODUCT(ISNUMBER('IBK_N3'!$O$5:$O$43)*'IBK_N3'!$B$5:$B$43) | C8: =IFERROR(SUMPRODUCT(ISNUMBER('IBK_N3'!$O$5:$O$43)*'IBK_N3'!$B$5:$B$43*'IBK_N3'!$C$5:$C$43)/SUMPRODUCT(ISNUMBER('IBK_N3'!$O$5:$O$43)*'IBK_N3'!$B$5:$B$43),"") | D8: =IFERROR(SUMPRODUCT(ISNUMBER('IBK_N3'!$O$5:$O$43)*'IBK_N3'!$B$5:$B$43*'IBK_N3'!$D$5:$D$43)/SUMPRODUCT(ISNUMBER('IBK_N3'!$O$5:$O$43)*'IBK_N3'!$B$5:$B$43),"") | E8: =IFERROR(SUMPRODUCT(ISNUMBER('IBK_N3'!$O$5:$O$43)*'IBK_N3'!$B$5:$B$43*'IBK_N3'!$E$5:$E$43)/SUMPRODUCT(ISNUMBER('IBK_N3'!$O$5:$O$43)*'IBK_N3'!$B$5:$B$43),"") | F8: =IFERROR(SUMPRODUCT(ISNUMBER('IBK_N3'!$O$5:$O$43)*'IBK_N3'!$B$5:$B$43*'IBK_N3'!$O$5:$O$43)/SUMPRODUCT(ISNUMBER('IBK_N3'!$O$5:$O$43)*'IBK_N3'!$B$5:$B$43),"") | G8: =IFERROR(D8/F8-1,"") | H8: =IFERROR(E8/F8-1,"") | I8: =IF(H8="","",IF(OR(H8<-0.25,H8>0.3),"ROJO",IF(OR(H8<-0.1,H8>0.15),"AMBAR","VERDE"))) | J8: =SUMPRODUCT(ISNUMBER('IBK_N3'!$AA$5:$AA$43)*'IBK_N3'!$Y$5:$Y$43) | K8: =IFERROR(J8/B8,"") | L8: =IFERROR(SUMPRODUCT(ISNUMBER('IBK_N3'!$AA$5:$AA$43)*'IBK_N3'!$Y$5:$Y$43*'IBK_N3'!$Z$5:$Z$43)/SUMPRODUCT(ISNUMBER('IBK_N3'!$AA$5:$AA$43)*'IBK_N3'!$Y$5:$Y$43),"") | M8: =IFERROR(SUMPRODUCT(ISNUMBER('IBK_N3'!$AA$5:$AA$43)*'IBK_N3'!$Y$5:$Y$43*'IBK_N3'!$AA$5:$AA$43)/SUMPRODUCT(ISNUMBER('IBK_N3'!$AA$5:$AA$43)*'IBK_N3'!$Y$5:$Y$43),"") | N8: =IFERROR(L8/M8-1,"") | O8: =IF(N8="","",IF(OR(N8<-0.25,N8>0.3),"ROJO",IF(OR(N8<-0.1,N8>0.15),"AMBAR","VERDE")))
A9: SSFF_con_BCP | B9: =SUMPRODUCT(ISNUMBER('SSFF_con_BCP'!$O$5:$O$43)*'SSFF_con_BCP'!$B$5:$B$43) | C9: =IFERROR(SUMPRODUCT(ISNUMBER('SSFF_con_BCP'!$O$5:$O$43)*'SSFF_con_BCP'!$B$5:$B$43*'SSFF_con_BCP'!$C$5:$C$43)/SUMPRODUCT(ISNUMBER('SSFF_con_BCP'!$O$5:$O$43)*'SSFF_con_BCP'!$B$5:$B$43),"") | D9: =IFERROR(SUMPRODUCT(ISNUMBER('SSFF_con_BCP'!$O$5:$O$43)*'SSFF_con_BCP'!$B$5:$B$43*'SSFF_con_BCP'!$D$5:$D$43)/SUMPRODUCT(ISNUMBER('SSFF_con_BCP'!$O$5:$O$43)*'SSFF_con_BCP'!$B$5:$B$43),"") | E9: =IFERROR(SUMPRODUCT(ISNUMBER('SSFF_con_BCP'!$O$5:$O$43)*'SSFF_con_BCP'!$B$5:$B$43*'SSFF_con_BCP'!$E$5:$E$43)/SUMPRODUCT(ISNUMBER('SSFF_con_BCP'!$O$5:$O$43)*'SSFF_con_BCP'!$B$5:$B$43),"") | F9: =IFERROR(SUMPRODUCT(ISNUMBER('SSFF_con_BCP'!$O$5:$O$43)*'SSFF_con_BCP'!$B$5:$B$43*'SSFF_con_BCP'!$O$5:$O$43)/SUMPRODUCT(ISNUMBER('SSFF_con_BCP'!$O$5:$O$43)*'SSFF_con_BCP'!$B$5:$B$43),"") | G9: =IFERROR(D9/F9-1,"") | H9: =IFERROR(E9/F9-1,"") | I9: =IF(H9="","",IF(OR(H9<-0.25,H9>0.3),"ROJO",IF(OR(H9<-0.1,H9>0.15),"AMBAR","VERDE"))) | J9: =SUMPRODUCT(ISNUMBER('SSFF_con_BCP'!$X$5:$X$43)*'SSFF_con_BCP'!$V$5:$V$43) | K9: =IFERROR(J9/B9,"") | L9: =IFERROR(SUMPRODUCT(ISNUMBER('SSFF_con_BCP'!$X$5:$X$43)*'SSFF_con_BCP'!$V$5:$V$43*'SSFF_con_BCP'!$W$5:$W$43)/SUMPRODUCT(ISNUMBER('SSFF_con_BCP'!$X$5:$X$43)*'SSFF_con_BCP'!$V$5:$V$43),"") | M9: =IFERROR(SUMPRODUCT(ISNUMBER('SSFF_con_BCP'!$X$5:$X$43)*'SSFF_con_BCP'!$V$5:$V$43*'SSFF_con_BCP'!$X$5:$X$43)/SUMPRODUCT(ISNUMBER('SSFF_con_BCP'!$X$5:$X$43)*'SSFF_con_BCP'!$V$5:$V$43),"") | N9: =IFERROR(L9/M9-1,"") | O9: =IF(N9="","",IF(OR(N9<-0.25,N9>0.3),"ROJO",IF(OR(N9<-0.1,N9>0.15),"AMBAR","VERDE")))
A10: SSFF_sin_BCP | B10: =SUMPRODUCT(ISNUMBER('SSFF_sin_BCP'!$O$5:$O$43)*'SSFF_sin_BCP'!$B$5:$B$43) | C10: =IFERROR(SUMPRODUCT(ISNUMBER('SSFF_sin_BCP'!$O$5:$O$43)*'SSFF_sin_BCP'!$B$5:$B$43*'SSFF_sin_BCP'!$C$5:$C$43)/SUMPRODUCT(ISNUMBER('SSFF_sin_BCP'!$O$5:$O$43)*'SSFF_sin_BCP'!$B$5:$B$43),"") | D10: =IFERROR(SUMPRODUCT(ISNUMBER('SSFF_sin_BCP'!$O$5:$O$43)*'SSFF_sin_BCP'!$B$5:$B$43*'SSFF_sin_BCP'!$D$5:$D$43)/SUMPRODUCT(ISNUMBER('SSFF_sin_BCP'!$O$5:$O$43)*'SSFF_sin_BCP'!$B$5:$B$43),"") | E10: =IFERROR(SUMPRODUCT(ISNUMBER('SSFF_sin_BCP'!$O$5:$O$43)*'SSFF_sin_BCP'!$B$5:$B$43*'SSFF_sin_BCP'!$E$5:$E$43)/SUMPRODUCT(ISNUMBER('SSFF_sin_BCP'!$O$5:$O$43)*'SSFF_sin_BCP'!$B$5:$B$43),"") | F10: =IFERROR(SUMPRODUCT(ISNUMBER('SSFF_sin_BCP'!$O$5:$O$43)*'SSFF_sin_BCP'!$B$5:$B$43*'SSFF_sin_BCP'!$O$5:$O$43)/SUMPRODUCT(ISNUMBER('SSFF_sin_BCP'!$O$5:$O$43)*'SSFF_sin_BCP'!$B$5:$B$43),"") | G10: =IFERROR(D10/F10-1,"") | H10: =IFERROR(E10/F10-1,"") | I10: =IF(H10="","",IF(OR(H10<-0.25,H10>0.3),"ROJO",IF(OR(H10<-0.1,H10>0.15),"AMBAR","VERDE"))) | J10: =SUMPRODUCT(ISNUMBER('SSFF_sin_BCP'!$X$5:$X$43)*'SSFF_sin_BCP'!$V$5:$V$43) | K10: =IFERROR(J10/B10,"") | L10: =IFERROR(SUMPRODUCT(ISNUMBER('SSFF_sin_BCP'!$X$5:$X$43)*'SSFF_sin_BCP'!$V$5:$V$43*'SSFF_sin_BCP'!$W$5:$W$43)/SUMPRODUCT(ISNUMBER('SSFF_sin_BCP'!$X$5:$X$43)*'SSFF_sin_BCP'!$V$5:$V$43),"") | M10: =IFERROR(SUMPRODUCT(ISNUMBER('SSFF_sin_BCP'!$X$5:$X$43)*'SSFF_sin_BCP'!$V$5:$V$43*'SSFF_sin_BCP'!$X$5:$X$43)/SUMPRODUCT(ISNUMBER('SSFF_sin_BCP'!$X$5:$X$43)*'SSFF_sin_BCP'!$V$5:$V$43),"") | N10: =IFERROR(L10/M10-1,"") | O10: =IF(N10="","",IF(OR(N10<-0.25,N10>0.3),"ROJO",IF(OR(N10<-0.1,N10>0.15),"AMBAR","VERDE")))
A11: SISTEMA_5 | B11: =SUMPRODUCT(ISNUMBER('SISTEMA_5'!$O$5:$O$43)*'SISTEMA_5'!$B$5:$B$43) | C11: =IFERROR(SUMPRODUCT(ISNUMBER('SISTEMA_5'!$O$5:$O$43)*'SISTEMA_5'!$B$5:$B$43*'SISTEMA_5'!$C$5:$C$43)/SUMPRODUCT(ISNUMBER('SISTEMA_5'!$O$5:$O$43)*'SISTEMA_5'!$B$5:$B$43),"") | D11: =IFERROR(SUMPRODUCT(ISNUMBER('SISTEMA_5'!$O$5:$O$43)*'SISTEMA_5'!$B$5:$B$43*'SISTEMA_5'!$D$5:$D$43)/SUMPRODUCT(ISNUMBER('SISTEMA_5'!$O$5:$O$43)*'SISTEMA_5'!$B$5:$B$43),"") | E11: =IFERROR(SUMPRODUCT(ISNUMBER('SISTEMA_5'!$O$5:$O$43)*'SISTEMA_5'!$B$5:$B$43*'SISTEMA_5'!$E$5:$E$43)/SUMPRODUCT(ISNUMBER('SISTEMA_5'!$O$5:$O$43)*'SISTEMA_5'!$B$5:$B$43),"") | F11: =IFERROR(SUMPRODUCT(ISNUMBER('SISTEMA_5'!$O$5:$O$43)*'SISTEMA_5'!$B$5:$B$43*'SISTEMA_5'!$O$5:$O$43)/SUMPRODUCT(ISNUMBER('SISTEMA_5'!$O$5:$O$43)*'SISTEMA_5'!$B$5:$B$43),"") | G11: =IFERROR(D11/F11-1,"") | H11: =IFERROR(E11/F11-1,"") | I11: =IF(H11="","",IF(OR(H11<-0.25,H11>0.3),"ROJO",IF(OR(H11<-0.1,H11>0.15),"AMBAR","VERDE"))) | J11: =SUMPRODUCT(ISNUMBER('SISTEMA_5'!$X$5:$X$43)*'SISTEMA_5'!$V$5:$V$43) | K11: =IFERROR(J11/B11,"") | L11: =IFERROR(SUMPRODUCT(ISNUMBER('SISTEMA_5'!$X$5:$X$43)*'SISTEMA_5'!$V$5:$V$43*'SISTEMA_5'!$W$5:$W$43)/SUMPRODUCT(ISNUMBER('SISTEMA_5'!$X$5:$X$43)*'SISTEMA_5'!$V$5:$V$43),"") | M11: =IFERROR(SUMPRODUCT(ISNUMBER('SISTEMA_5'!$X$5:$X$43)*'SISTEMA_5'!$V$5:$V$43*'SISTEMA_5'!$X$5:$X$43)/SUMPRODUCT(ISNUMBER('SISTEMA_5'!$X$5:$X$43)*'SISTEMA_5'!$V$5:$V$43),"") | N11: =IFERROR(L11/M11-1,"") | O11: =IF(N11="","",IF(OR(N11<-0.25,N11>0.3),"ROJO",IF(OR(N11<-0.1,N11>0.15),"AMBAR","VERDE")))
A12: ENT_00001_BCP | B12: =SUMPRODUCT(ISNUMBER('ENT_00001_BCP'!$O$5:$O$43)*'ENT_00001_BCP'!$B$5:$B$43) | C12: =IFERROR(SUMPRODUCT(ISNUMBER('ENT_00001_BCP'!$O$5:$O$43)*'ENT_00001_BCP'!$B$5:$B$43*'ENT_00001_BCP'!$C$5:$C$43)/SUMPRODUCT(ISNUMBER('ENT_00001_BCP'!$O$5:$O$43)*'ENT_00001_BCP'!$B$5:$B$43),"") | D12: =IFERROR(SUMPRODUCT(ISNUMBER('ENT_00001_BCP'!$O$5:$O$43)*'ENT_00001_BCP'!$B$5:$B$43*'ENT_00001_BCP'!$D$5:$D$43)/SUMPRODUCT(ISNUMBER('ENT_00001_BCP'!$O$5:$O$43)*'ENT_00001_BCP'!$B$5:$B$43),"") | E12: =IFERROR(SUMPRODUCT(ISNUMBER('ENT_00001_BCP'!$O$5:$O$43)*'ENT_00001_BCP'!$B$5:$B$43*'ENT_00001_BCP'!$E$5:$E$43)/SUMPRODUCT(ISNUMBER('ENT_00001_BCP'!$O$5:$O$43)*'ENT_00001_BCP'!$B$5:$B$43),"") | F12: =IFERROR(SUMPRODUCT(ISNUMBER('ENT_00001_BCP'!$O$5:$O$43)*'ENT_00001_BCP'!$B$5:$B$43*'ENT_00001_BCP'!$O$5:$O$43)/SUMPRODUCT(ISNUMBER('ENT_00001_BCP'!$O$5:$O$43)*'ENT_00001_BCP'!$B$5:$B$43),"") | G12: =IFERROR(D12/F12-1,"") | H12: =IFERROR(E12/F12-1,"") | I12: =IF(H12="","",IF(OR(H12<-0.25,H12>0.3),"ROJO",IF(OR(H12<-0.1,H12>0.15),"AMBAR","VERDE"))) | J12: =SUMPRODUCT(ISNUMBER('ENT_00001_BCP'!$X$5:$X$43)*'ENT_00001_BCP'!$V$5:$V$43) | K12: =IFERROR(J12/B12,"") | L12: =IFERROR(SUMPRODUCT(ISNUMBER('ENT_00001_BCP'!$X$5:$X$43)*'ENT_00001_BCP'!$V$5:$V$43*'ENT_00001_BCP'!$W$5:$W$43)/SUMPRODUCT(ISNUMBER('ENT_00001_BCP'!$X$5:$X$43)*'ENT_00001_BCP'!$V$5:$V$43),"") | M12: =IFERROR(SUMPRODUCT(ISNUMBER('ENT_00001_BCP'!$X$5:$X$43)*'ENT_00001_BCP'!$V$5:$V$43*'ENT_00001_BCP'!$X$5:$X$43)/SUMPRODUCT(ISNUMBER('ENT_00001_BCP'!$X$5:$X$43)*'ENT_00001_BCP'!$V$5:$V$43),"") | N12: =IFERROR(L12/M12-1,"") | O12: =IF(N12="","",IF(OR(N12<-0.25,N12>0.3),"ROJO",IF(OR(N12<-0.1,N12>0.15),"AMBAR","VERDE")))
A13: ENT_00006_BBVA | B13: =SUMPRODUCT(ISNUMBER('ENT_00006_BBVA'!$O$5:$O$43)*'ENT_00006_BBVA'!$B$5:$B$43) | C13: =IFERROR(SUMPRODUCT(ISNUMBER('ENT_00006_BBVA'!$O$5:$O$43)*'ENT_00006_BBVA'!$B$5:$B$43*'ENT_00006_BBVA'!$C$5:$C$43)/SUMPRODUCT(ISNUMBER('ENT_00006_BBVA'!$O$5:$O$43)*'ENT_00006_BBVA'!$B$5:$B$43),"") | D13: =IFERROR(SUMPRODUCT(ISNUMBER('ENT_00006_BBVA'!$O$5:$O$43)*'ENT_00006_BBVA'!$B$5:$B$43*'ENT_00006_BBVA'!$D$5:$D$43)/SUMPRODUCT(ISNUMBER('ENT_00006_BBVA'!$O$5:$O$43)*'ENT_00006_BBVA'!$B$5:$B$43),"") | E13: =IFERROR(SUMPRODUCT(ISNUMBER('ENT_00006_BBVA'!$O$5:$O$43)*'ENT_00006_BBVA'!$B$5:$B$43*'ENT_00006_BBVA'!$E$5:$E$43)/SUMPRODUCT(ISNUMBER('ENT_00006_BBVA'!$O$5:$O$43)*'ENT_00006_BBVA'!$B$5:$B$43),"") | F13: =IFERROR(SUMPRODUCT(ISNUMBER('ENT_00006_BBVA'!$O$5:$O$43)*'ENT_00006_BBVA'!$B$5:$B$43*'ENT_00006_BBVA'!$O$5:$O$43)/SUMPRODUCT(ISNUMBER('ENT_00006_BBVA'!$O$5:$O$43)*'ENT_00006_BBVA'!$B$5:$B$43),"") | G13: =IFERROR(D13/F13-1,"") | H13: =IFERROR(E13/F13-1,"") | I13: =IF(H13="","",IF(OR(H13<-0.25,H13>0.3),"ROJO",IF(OR(H13<-0.1,H13>0.15),"AMBAR","VERDE"))) | J13: =SUMPRODUCT(ISNUMBER('ENT_00006_BBVA'!$X$5:$X$43)*'ENT_00006_BBVA'!$V$5:$V$43) | K13: =IFERROR(J13/B13,"") | L13: =IFERROR(SUMPRODUCT(ISNUMBER('ENT_00006_BBVA'!$X$5:$X$43)*'ENT_00006_BBVA'!$V$5:$V$43*'ENT_00006_BBVA'!$W$5:$W$43)/SUMPRODUCT(ISNUMBER('ENT_00006_BBVA'!$X$5:$X$43)*'ENT_00006_BBVA'!$V$5:$V$43),"") | M13: =IFERROR(SUMPRODUCT(ISNUMBER('ENT_00006_BBVA'!$X$5:$X$43)*'ENT_00006_BBVA'!$V$5:$V$43*'ENT_00006_BBVA'!$X$5:$X$43)/SUMPRODUCT(ISNUMBER('ENT_00006_BBVA'!$X$5:$X$43)*'ENT_00006_BBVA'!$V$5:$V$43),"") | N13: =IFERROR(L13/M13-1,"") | O13: =IF(N13="","",IF(OR(N13<-0.25,N13>0.3),"ROJO",IF(OR(N13<-0.1,N13>0.15),"AMBAR","VERDE")))
A14: ENT_00004_Scotiabank | B14: =SUMPRODUCT(ISNUMBER('ENT_00004_Scotiabank'!$O$5:$O$43)*'ENT_00004_Scotiabank'!$B$5:$B$43) | C14: =IFERROR(SUMPRODUCT(ISNUMBER('ENT_00004_Scotiabank'!$O$5:$O$43)*'ENT_00004_Scotiabank'!$B$5:$B$43*'ENT_00004_Scotiabank'!$C$5:$C$43)/SUMPRODUCT(ISNUMBER('ENT_00004_Scotiabank'!$O$5:$O$43)*'ENT_00004_Scotiabank'!$B$5:$B$43),"") | D14: =IFERROR(SUMPRODUCT(ISNUMBER('ENT_00004_Scotiabank'!$O$5:$O$43)*'ENT_00004_Scotiabank'!$B$5:$B$43*'ENT_00004_Scotiabank'!$D$5:$D$43)/SUMPRODUCT(ISNUMBER('ENT_00004_Scotiabank'!$O$5:$O$43)*'ENT_00004_Scotiabank'!$B$5:$B$43),"") | E14: =IFERROR(SUMPRODUCT(ISNUMBER('ENT_00004_Scotiabank'!$O$5:$O$43)*'ENT_00004_Scotiabank'!$B$5:$B$43*'ENT_00004_Scotiabank'!$E$5:$E$43)/SUMPRODUCT(ISNUMBER('ENT_00004_Scotiabank'!$O$5:$O$43)*'ENT_00004_Scotiabank'!$B$5:$B$43),"") | F14: =IFERROR(SUMPRODUCT(ISNUMBER('ENT_00004_Scotiabank'!$O$5:$O$43)*'ENT_00004_Scotiabank'!$B$5:$B$43*'ENT_00004_Scotiabank'!$O$5:$O$43)/SUMPRODUCT(ISNUMBER('ENT_00004_Scotiabank'!$O$5:$O$43)*'ENT_00004_Scotiabank'!$B$5:$B$43),"") | G14: =IFERROR(D14/F14-1,"") | H14: =IFERROR(E14/F14-1,"") | I14: =IF(H14="","",IF(OR(H14<-0.25,H14>0.3),"ROJO",IF(OR(H14<-0.1,H14>0.15),"AMBAR","VERDE"))) | J14: =SUMPRODUCT(ISNUMBER('ENT_00004_Scotiabank'!$X$5:$X$43)*'ENT_00004_Scotiabank'!$V$5:$V$43) | K14: =IFERROR(J14/B14,"") | L14: =IFERROR(SUMPRODUCT(ISNUMBER('ENT_00004_Scotiabank'!$X$5:$X$43)*'ENT_00004_Scotiabank'!$V$5:$V$43*'ENT_00004_Scotiabank'!$W$5:$W$43)/SUMPRODUCT(ISNUMBER('ENT_00004_Scotiabank'!$X$5:$X$43)*'ENT_00004_Scotiabank'!$V$5:$V$43),"") | M14: =IFERROR(SUMPRODUCT(ISNUMBER('ENT_00004_Scotiabank'!$X$5:$X$43)*'ENT_00004_Scotiabank'!$V$5:$V$43*'ENT_00004_Scotiabank'!$X$5:$X$43)/SUMPRODUCT(ISNUMBER('ENT_00004_Scotiabank'!$X$5:$X$43)*'ENT_00004_Scotiabank'!$V$5:$V$43),"") | N14: =IFERROR(L14/M14-1,"") | O14: =IF(N14="","",IF(OR(N14<-0.25,N14>0.3),"ROJO",IF(OR(N14<-0.1,N14>0.15),"AMBAR","VERDE")))
A15: ENT_00142_Falabella | B15: =SUMPRODUCT(ISNUMBER('ENT_00142_Falabella'!$O$5:$O$43)*'ENT_00142_Falabella'!$B$5:$B$43) | C15: =IFERROR(SUMPRODUCT(ISNUMBER('ENT_00142_Falabella'!$O$5:$O$43)*'ENT_00142_Falabella'!$B$5:$B$43*'ENT_00142_Falabella'!$C$5:$C$43)/SUMPRODUCT(ISNUMBER('ENT_00142_Falabella'!$O$5:$O$43)*'ENT_00142_Falabella'!$B$5:$B$43),"") | D15: =IFERROR(SUMPRODUCT(ISNUMBER('ENT_00142_Falabella'!$O$5:$O$43)*'ENT_00142_Falabella'!$B$5:$B$43*'ENT_00142_Falabella'!$D$5:$D$43)/SUMPRODUCT(ISNUMBER('ENT_00142_Falabella'!$O$5:$O$43)*'ENT_00142_Falabella'!$B$5:$B$43),"") | E15: =IFERROR(SUMPRODUCT(ISNUMBER('ENT_00142_Falabella'!$O$5:$O$43)*'ENT_00142_Falabella'!$B$5:$B$43*'ENT_00142_Falabella'!$E$5:$E$43)/SUMPRODUCT(ISNUMBER('ENT_00142_Falabella'!$O$5:$O$43)*'ENT_00142_Falabella'!$B$5:$B$43),"") | F15: =IFERROR(SUMPRODUCT(ISNUMBER('ENT_00142_Falabella'!$O$5:$O$43)*'ENT_00142_Falabella'!$B$5:$B$43*'ENT_00142_Falabella'!$O$5:$O$43)/SUMPRODUCT(ISNUMBER('ENT_00142_Falabella'!$O$5:$O$43)*'ENT_00142_Falabella'!$B$5:$B$43),"") | G15: =IFERROR(D15/F15-1,"") | H15: =IFERROR(E15/F15-1,"") | I15: =IF(H15="","",IF(OR(H15<-0.25,H15>0.3),"ROJO",IF(OR(H15<-0.1,H15>0.15),"AMBAR","VERDE"))) | J15: =SUMPRODUCT(ISNUMBER('ENT_00142_Falabella'!$X$5:$X$43)*'ENT_00142_Falabella'!$V$5:$V$43) | K15: =IFERROR(J15/B15,"") | L15: =IFERROR(SUMPRODUCT(ISNUMBER('ENT_00142_Falabella'!$X$5:$X$43)*'ENT_00142_Falabella'!$V$5:$V$43*'ENT_00142_Falabella'!$W$5:$W$43)/SUMPRODUCT(ISNUMBER('ENT_00142_Falabella'!$X$5:$X$43)*'ENT_00142_Falabella'!$V$5:$V$43),"") | M15: =IFERROR(SUMPRODUCT(ISNUMBER('ENT_00142_Falabella'!$X$5:$X$43)*'ENT_00142_Falabella'!$V$5:$V$43*'ENT_00142_Falabella'!$X$5:$X$43)/SUMPRODUCT(ISNUMBER('ENT_00142_Falabella'!$X$5:$X$43)*'ENT_00142_Falabella'!$V$5:$V$43),"") | N15: =IFERROR(L15/M15-1,"") | O15: =IF(N15="","",IF(OR(N15<-0.25,N15>0.3),"ROJO",IF(OR(N15<-0.1,N15>0.15),"AMBAR","VERDE")))

Sheet FACTORES_DESARROLLO
A1: FACTORES DE DESARROLLO h -> 12 meses
A2: Chain-ladder ponderado por n. Deben decrecer con el horizonte.
A4: poblacion | B4: 3m | C4: 4m | D4: 5m | E4: 6m | F4: 7m | G4: 8m | H4: 9m | I4: 10m | J4: 11m | K4: 12m
A5: IBK_general | B5: 13.724816 | C5: 4.1733284 | D5: 2.7268733 | E5: 2.0882243 | F5: 1.7200924 | G5: 1.4563942 | H5: 1.285172 | I5: 1.16266 | J5: 1.0711409 | K5: 1
A6: IBK_N1 | B6: 19.022222 | C6: 6.0696203 | D6: 3.6863469 | E6: 2.6015625 | F6: 2.068323 | G6: 1.6567164 | H6: 1.4210526 | I6: 1.2742347 | J6: 1.0953947 | K6: 1
A7: IBK_N2 | B7: 14.830303 | C7: 5.0139442 | D7: 3.0252404 | E7: 2.3049451 | F7: 1.8603104 | G7: 1.5489231 | H7: 1.3452699 | I7: 1.1900709 | J7: 1.0830465 | K7: 1
A8: IBK_N3 | B8: 12.675497 | C8: 3.7957362 | D8: 2.5571142 | E8: 1.9762519 | F8: 1.6432711 | G8: 1.4065773 | H8: 1.2511848 | I8: 1.1409836 | J8: 1.0642202 | K8: 1
A9: SSFF_con_BCP | B9: 22.351549 | C9: 5.2444151 | D9: 3.0327167 | E9: 2.2281254 | F9: 1.7901006 | G9: 1.5215924 | H9: 1.3375362 | I9: 1.1985379 | J9: 1.0883006 | K9: 1
A10: SSFF_sin_BCP | B10: 20.738992 | C10: 4.9068398 | D10: 2.869834 | E10: 2.1282253 | F10: 1.7273307 | G10: 1.4800073 | H10: 1.311355 | I10: 1.1841568 | J10: 1.0815362 | K10: 1
A11: SISTEMA_5 | B11: 19.639243 | C11: 4.9644601 | D11: 2.9597765 | E11: 2.1958024 | F11: 1.7742341 | G11: 1.5067714 | H11: 1.3256681 | I11: 1.1904662 | J11: 1.0844833 | K11: 1
A12: ENT_00001_BCP | B12: 33.697115 | C12: 7.6178344 | D12: 4.0819113 | E12: 2.829653 | F12: 2.1427292 | G12: 1.7434402 | H12: 1.4704918 | I12: 1.2682927 | J12: 1.120025 | K12: 1
A13: ENT_00006_BBVA | B13: 22.085612 | C13: 5.0596568 | D13: 3.0741476 | E13: 2.2418829 | F13: 1.7827047 | G13: 1.5150082 | H13: 1.3296585 | I13: 1.1956228 | J13: 1.0884904 | K13: 1
A14: ENT_00004_Scotiabank | B14: 14.558442 | C14: 4.2553191 | D14: 2.7459954 | E14: 2.1057192 | F14: 1.7307692 | G14: 1.4907975 | H14: 1.3293217 | I14: 1.1994077 | J14: 1.0995475 | K14: 1
A15: ENT_00142_Falabella | B15: 19.582435 | C15: 4.7599251 | D15: 2.6231166 | E15: 1.9833021 | F15: 1.6520213 | G15: 1.4307103 | H15: 1.2838671 | I15: 1.1663913 | J15: 1.0698712 | K15: 1

Sheet IBK_general
A1: IBK general
A2: Interbank, poblacion clean
A4: codmes | B4: n | C4: PD sin calibrar | D4: PD cal vigente | E4: PD cal NUEVA | F4: mora 3m | G4: mora 4m | H4: mora 5m | I4: mora 6m | J4: mora 7m | K4: mora 8m | L4: mora 9m | M4: mora 10m | N4: mora 11m | O4: mora 12m | P4: ft ciclo | Q4: inflacion % | R4: madurez | S4: mora base | T4: factor h->12 | U4: proy mediana | V4: proy V1 | W4: proy V2 | X4: proy V3 | Y4: n visible IBK | Z4: PD cal NUEVA visible | AA4: mora 12m visible | AB4: EC vigente | AC4: EC NUEVA | AD4: EC NUEVA vs proy | AE4: EC NUEVA visible
A5: 202303 | B5: 6747 | C5: 0.1237198 | D5: 0.15572498 | E5: 0.13138193 | F5: 0.011857122 | G5: 0.041203498 | H5: 0.057803468 | I5: 0.076923077 | J5: 0.0961909 | K5: 0.11783015 | L5: 0.1332444 | M5: 0.14673188 | N5: 0.15532829 | O5: 0.16436935 | P5: 0.23130779 | Q5: 8.6661549 | R5: 12 | S5: 0.16436935 | T5: 1 | U5: 0.16436935 | Y5: 6405 | Z5: 0.1318232 | AA5: 0.16299766 | AB5: =IFERROR(D5/O5-1,"") | AC5: =IFERROR(E5/O5-1,"") | AD5: =IFERROR(E5/U5-1,"") | AE5: =IFERROR(Z5/AA5-1,"")
A6: 202304 | B6: 5942 | C6: 0.11411484 | D6: 0.14385094 | E6: 0.11766581 | F6: 0.0097610232 | G6: 0.033658701 | H6: 0.050488051 | I6: 0.06866375 | J6: 0.084819926 | K6: 0.10299562 | L6: 0.11814204 | M6: 0.13059576 | N6: 0.14018849 | O6: 0.14692023 | P6: 0.20398831 | Q6: 8.0421126 | R6: 12 | S6: 0.14692023 | T6: 1 | U6: 0.14692023 | Y6: 5708 | Z6: 0.11775088 | AA6: 0.14716188 | AB6: =IFERROR(D6/O6-1,"") | AC6: =IFERROR(E6/O6-1,"") | AD6: =IFERROR(E6/U6-1,"") | AE6: =IFERROR(Z6/AA6-1,"")
A7: 202305 | B7: 7417 | C7: 0.11612884 | D7: 0.14637197 | E7: 0.12110224 | F7: 0.0094377781 | G7: 0.036672509 | H7: 0.057705272 | I7: 0.075906701 | J7: 0.093703654 | K7: 0.11379264 | L7: 0.12956721 | M7: 0.14304975 | N7: 0.1512741 | O7: 0.15774572 | P7: 0.20154202 | Q7: 7.9862335 | R7: 12 | S7: 0.15774572 | T7: 1 | U7: 0.15774572 | Y7: 7070 | Z7: 0.12104071 | AA7: 0.15742574 | AB7: =IFERROR(D7/O7-1,"") | AC7: =IFERROR(E7/O7-1,"") | AD7: =IFERROR(E7/U7-1,"") | AE7: =IFERROR(Z7/AA7-1,"")
A8: 202306 | B8: 5236 | C8: 0.10819611 | D8: 0.13625009 | E8: 0.11068947 | F8: 0.011459129 | G8: 0.033040489 | H8: 0.054239878 | I8: 0.071237586 | J8: 0.084033613 | K8: 0.10103132 | L8: 0.11306341 | M8: 0.12089381 | N8: 0.13101604 | O8: 0.13770053 | P8: 0.14563116 | Q8: 6.7090957 | R8: 12 | S8: 0.13770053 | T8: 1 | U8: 0.13770053 | Y8: 4949 | Z8: 0.11034239 | AA8: 0.13457264 | AB8: =IFERROR(D8/O8-1,"") | AC8: =IFERROR(E8/O8-1,"") | AD8: =IFERROR(E8/U8-1,"") | AE8: =IFERROR(Z8/AA8-1,"")
A9: 202307 | B9: 3361 | C9: 0.089819245 | D9: 0.092360497 | E9: 0.086074495 | F9: 0.0056530794 | G9: 0.018744421 | H9: 0.026480214 | I9: 0.036298721 | J9: 0.045522166 | K9: 0.055340672 | L9: 0.061291282 | M9: 0.068134484 | N9: 0.075275216 | O9: 0.079143112 | P9: 0.11544766 | Q9: 6.0196325 | R9: 12 | S9: 0.079143112 | T9: 1 | U9: 0.079143112 | Y9: 3133 | Z9: 0.084289583 | AA9: 0.075646345 | AB9: =IFERROR(D9/O9-1,"") | AC9: =IFERROR(E9/O9-1,"") | AD9: =IFERROR(E9/U9-1,"") | AE9: =IFERROR(Z9/AA9-1,"")
A10: 202308 | B10: 4277 | C10: 0.095499117 | D10: 0.098508191 | E10: 0.092852791 | F10: 0.0049099836 | G10: 0.017769465 | H10: 0.028524667 | I10: 0.036474164 | J10: 0.047696984 | K10: 0.057049334 | L10: 0.066869301 | M10: 0.073415946 | N10: 0.077624503 | O10: 0.082768296 | P10: 0.10524205 | Q10: 5.7865118 | R10: 12 | S10: 0.082768296 | T10: 1 | U10: 0.082768296 | Y10: 4034 | Z10: 0.091897221 | AA10: 0.080317303 | AB10: =IFERROR(D10/O10-1,"") | AC10: =IFERROR(E10/O10-1,"") | AD10: =IFERROR(E10/U10-1,"") | AE10: =IFERROR(Z10/AA10-1,"")
A11: 202309 | B11: 2877 | C11: 0.093220388 | D11: 0.088391922 | E11: 0.0882549 | F11: 0.0066041015 | G11: 0.022245395 | H11: 0.028849496 | I11: 0.040319778 | J11: 0.049356969 | K11: 0.060827251 | L11: 0.067431352 | M11: 0.072297532 | N11: 0.077511296 | O11: 0.083767814 | P11: 0.082642878 | Q11: 5.2702928 | R11: 12 | S11: 0.083767814 | T11: 1 | U11: 0.083767814 | Y11: 2676 | Z11: 0.086385606 | AA11: 0.081464873 | AB11: =IFERROR(D11/O11-1,"") | AC11: =IFERROR(E11/O11-1,"") | AD11: =IFERROR(E11/U11-1,"") | AE11: =IFERROR(Z11/AA11-1,"")
A12: 202310 | B12: 2474 | C12: 0.094843223 | D12: 0.095298439 | E12: 0.084867105 | F12: 0.0060630558 | G12: 0.014955538 | H12: 0.028698464 | I12: 0.036378335 | J12: 0.044866613 | K12: 0.051333872 | L12: 0.057801132 | M12: 0.061843169 | N12: 0.067097817 | O12: 0.071139854 | P12: 0.049681202 | Q12: 4.5173693 | R12: 12 | S12: 0.071139854 | T12: 1 | U12: 0.071139854 | Y12: 2357 | Z12: 0.08301644 | AA12: 0.070852779 | AB12: =IFERROR(D12/O12-1,"") | AC12: =IFERROR(E12/O12-1,"") | AD12: =IFERROR(E12/U12-1,"") | AE12: =IFERROR(Z12/AA12-1,"")
A13: 202311 | B13: 2866 | C13: 0.13025806 | D13: 0.13194765 | E13: 0.12171049 | F13: 0.0052337753 | G13: 0.034193999 | H13: 0.05722261 | I13: 0.069085834 | J13: 0.083042568 | K13: 0.098743894 | L13: 0.10397767 | M13: 0.11304955 | N13: 0.12002791 | O13: 0.13189114 | P13: 0.017692212 | Q13: 3.7866642 | R13: 12 | S13: 0.13189114 | T13: 1 | U13: 0.13189114 | Y13: 2657 | Z13: 0.12036504 | AA13: 0.12721114 | AB13: =IFERROR(D13/O13-1,"") | AC13: =IFERROR(E13/O13-1,"") | AD13: =IFERROR(E13/U13-1,"") | AE13: =IFERROR(Z13/AA13-1,"")
A14: 202312 | B14: 3376 | C14: 0.14216821 | D14: 0.14358837 | E14: 0.13144005 | F14: 0.013625592 | G14: 0.046504739 | H14: 0.073459716 | I14: 0.091528436 | J14: 0.10367299 | K14: 0.1146327 | L14: 0.12588863 | M14: 0.13477488 | N14: 0.14810427 | O14: 0.15817536 | P14: 0.0012463847 | Q14: 3.4110022 | R14: 12 | S14: 0.15817536 | T14: 1 | U14: 0.15817536 | Y14: 3059 | Z14: 0.13183773 | AA14: 0.15397189 | AB14: =IFERROR(D14/O14-1,"") | AC14: =IFERROR(E14/O14-1,"") | AD14: =IFERROR(E14/U14-1,"") | AE14: =IFERROR(Z14/AA14-1,"")
A15: 202401 | B15: 4019 | C15: 0.12586277 | D15: 0.11865059 | E15: 0.1097944 | F15: 0.0097039064 | G15: 0.036576263 | H15: 0.055735258 | I15: 0.068673799 | J15: 0.074147798 | K15: 0.082109978 | L15: 0.089574521 | M15: 0.1030107 | N15: 0.11047524 | O15: 0.11868624 | P15: -0.019064283 | Q15: 2.947058 | R15: 12 | S15: 0.11868624 | T15: 1 | U15: 0.11868624 | Y15: 3599 | Z15: 0.10890536 | AA15: 0.11614337 | AB15: =IFERROR(D15/O15-1,"") | AC15: =IFERROR(E15/O15-1,"") | AD15: =IFERROR(E15/U15-1,"") | AE15: =IFERROR(Z15/AA15-1,"")
A16: 202402 | B16: 3916 | C16: 0.12972534 | D16: 0.12239881 | E16: 0.11393006 | F16: 0.012512768 | G16: 0.040091931 | H16: 0.05566905 | I16: 0.06639428 | J16: 0.07711951 | K16: 0.086312564 | L16: 0.098825332 | M16: 0.11287028 | N16: 0.12538304 | O16: 0.13406537 | P16: -0.019828668 | Q16: 2.9295976 | R16: 12 | S16: 0.13406537 | T16: 1 | U16: 0.13406537 | Y16: 3533 | Z16: 0.11284441 | AA16: 0.13274837 | AB16: =IFERROR(D16/O16-1,"") | AC16: =IFERROR(E16/O16-1,"") | AD16: =IFERROR(E16/U16-1,"") | AE16: =IFERROR(Z16/AA16-1,"")
... A32: 202506 | B32: 2259 | C32: 0.089828593 | D32: 0.085248871 | E32: 0.064312447 | F32: 0.0022133687 | G32: 0.0097388225 | H32: 0.016378929 | I32: 0.023461709 | J32: 0.03187251 | K32: 0.038069942 | L32: 0.041611332 | M32: 0.048251439 | N32: 0.051350155 | O32: 0.054448871 | P32: -0.073765695 | Q32: 1.697547 | R32: 12 | S32: 0.054448871 | T32: 1 | U32: 0.054448871 | Y32: 1985 | Z32: 0.062608002 | AA32: 0.050881612 | AB32: =IFERROR(D32/O32-1,"") | AC32: =IFERROR(E32/O32-1,"") | AD32: =IFERROR(E32/U32-1,"") | AE32: =IFERROR(Z32/AA32-1,"")
A33: 202507 | B33: 3092 | C33: 0.09961475 | D33: 0.094917748 | E33: 0.074698054 | F33: 0.0042043984 | G33: 0.01228978 | H33: 0.022639069 | I33: 0.027166882 | J33: 0.032988357 | K33: 0.037516171 | L33: 0.044954722 | M33: 0.052716688 | N33: 0.057891332 | P33: -0.073640896 | Q33: 1.7003977 | R33: 11 | S33: 0.057891332 | T33: 1.0711409 | U33: 0.062009776 | V33: 0.061383272 | W33: 0.062258636 | X33: 0.063218319 | Y33: 2705 | Z33: 0.071082782 | AB33: =IFERROR(D33/O33-1,"") | AC33: =IFERROR(E33/O33-1,"") | AD33: =IFERROR(E33/U33-1,"") | AE33: =IFERROR(Z33/AA33-1,"")
A34: 202508 | B34: 3056 | C34: 0.096165002 | D34: 0.091328032 | E34: 0.070116296 | F34: 0.0055628272 | G34: 0.017670157 | H34: 0.025850785 | I34: 0.033704188 | J34: 0.038612565 | K34: 0.044829843 | L34: 0.052356021 | M34: 0.060536649 | P34: -0.10033144 | Q34: 1.0907218 | R34: 10 | S34: 0.060536649 | T34: 1.16266 | U34: 0.070383541 | V34: 0.069720793 | W34: 0.07129536 | X34: 0.073915757 | Y34: 2672 | Z34: 0.067043592 | AB34: =IFERROR(D34/O34-1,"") | AC34: =IFERROR(E34/O34-1,"") | AD34: =IFERROR(E34/U34-1,"") | AE34: =IFERROR(Z34/AA34-1,"")
A35: 202509 | B35: 3136 | C35: 0.098972976 | D35: 0.094113533 | E35: 0.07319844 | F35: 0.0057397959 | G35: 0.017538265 | H35: 0.025191327 | I35: 0.031887755 | J35: 0.037308673 | K35: 0.043367347 | L35: 0.046875 | P35: -0.094338164 | Q35: 1.2276226 | R35: 9 | S35: 0.046875 | T35: 1.285172 | U35: 0.060242436 | V35: 0.058746111 | W35: 0.062081473 | X35: 0.063180296 | Y35: 2742 | Z35: 0.069893857 | AB35: =IFERROR(D35/O35-1,"") | AC35: =IFERROR(E35/O35-1,"") | AD35: =IFERROR(E35/U35-1,"") | AE35: =IFERROR(Z35/AA35-1,"")
A36: 202510 | B36: 3227 | C36: 0.094392252 | D36: 0.089712843 | E36: 0.068591051 | F36: 0.0040285095 | G36: 0.016733808 | H36: 0.023551286 | I36: 0.029439108 | J36: 0.038115897 | K36: 0.046482801 | P36: -0.097186463 | Q36: 1.1625606 | R36: 8 | S36: 0.046482801 | T36: 1.4563942 | U36: 0.067697283 | V36: 0.065940273 | W36: 0.068313117 | X36: 0.072320263 | Y36: 2781 | Z36: 0.065580935 | AB36: =IFERROR(D36/O36-1,"") | AC36: =IFERROR(E36/O36-1,"") | AD36: =IFERROR(E36/U36-1,"") | AE36: =IFERROR(Z36/AA36-1,"")
A37: 202511 | B37: 3016 | C37: 0.099025191 | D37: 0.094348219 | E37: 0.073531271 | F37: 0.0039787798 | G37: 0.018567639 | H37: 0.028514589 | I37: 0.037798408 | J37: 0.045092838 | P37: -0.095195045 | Q37: 1.2080494 | R37: 7 | S37: 0.045092838 | T37: 1.7200924 | U37: 0.077563847 | V37: 0.075792292 | W37: 0.078319602 | X37: 0.081976542 | Y37: 2569 | Z37: 0.070054053 | AB37: =IFERROR(D37/O37-1,"") | AC37: =IFERROR(E37/O37-1,"") | AD37: =IFERROR(E37/U37-1,"") | AE37: =IFERROR(Z37/AA37-1,"")
A38: 202512 | B38: 3285 | C38: 0.10310713 | D38: 0.098163468 | E38: 0.077449696 | F38: 0.0057838661 | G38: 0.020395738 | H38: 0.0304414 | I38: 0.042313546 | P38: -0.090738963 | Q38: 1.3098369 | R38: 6 | S38: 0.042313546 | T38: 2.0882243 | U38: 0.088360176 | V38: 0.084767234 | W38: 0.090562646 | X38: 0.097878393 | Y38: 2865 | Z38: 0.074513933 | AB38: =IFERROR(D38/O38-1,"") | AC38: =IFERROR(E38/O38-1,"") | AD38: =IFERROR(E38/U38-1,"") | AE38: =IFERROR(Z38/AA38-1,"")
A39: 202601 | B39: 3914 | C39: 0.097772737 | D39: 0.09307272 | E39: 0.072344478 | F39: 0.0071538068 | G39: 0.025804803 | H39: 0.038579458 | P39: -0.082751237 | Q39: 1.4922957 | R39: 5 | S39: 0.038579458 | T39: 2.7268733 | U39: 0.1052013 | V39: 0.097809141 | W39: 0.11198177 | X39: 0.12362116 | Y39: 3291 | Z39: 0.0677021 | AB39: =IFERROR(D39/O39-1,"") | AC39: =IFERROR(E39/O39-1,"") | AD39: =IFERROR(E39/U39-1,"") | AE39: =IFERROR(Z39/AA39-1,"")
A40: 202602 | B40: 3664 | C40: 0.098976439 | D40: 0.094103664 | E40: 0.079363752 | F40: 0.0095524017 | G40: 0.024836245 | P40: -0.037038893 | Q40: 2.5364749 | R40: 4 | S40: 0.024836245 | T40: 4.1733284 | U40: 0.1036498 | V40: 0.098604047 | W40: 0.10968347 | X40: 0.12715053 | Y40: 3145 | Z40: 0.075319056 | AB40: =IFERROR(D40/O40-1,"") | AC40: =IFERROR(E40/O40-1,"") | AD40: =IFERROR(E40/U40-1,"") | AE40: =IFERROR(Z40/AA40-1,"")
A41: 202603 | B41: 4269 | C41: 0.10215139 | D41: 0.097274933 | E41: 0.090227935 | F41: 0.0058561724 | P41: 0.014389803 | Q41: 3.7112293 | R41: 3 | S41: 0.0058561724 | T41: 13.724816 | U41: 0.080374887 | V41: 0.06995686 | W41: 0.081583802 | X41: 0.11252217 | Y41: 3623 | Z41: 0.085521044 | AB41: =IFERROR(D41/O41-1,"") | AC41: =IFERROR(E41/O41-1,"") | AD41: =IFERROR(E41/U41-1,"") | AE41: =IFERROR(Z41/AA41-1,"")
A42: 202604 | B42: 4047 | C42: 0.10496608 | D42: 0.098688834 | E42: 0.095354569 | P42: 0.024185191 | Q42: 3.9349794 | Y42: 3438 | Z42: 0.090227083 | AB42: =IFERROR(D42/O42-1,"") | AC42: =IFERROR(E42/O42-1,"") | AD42: =IFERROR(E42/U42-1,"") | AE42: =IFERROR(Z42/AA42-1,"")
A43: 202605 | B43: 4936 | C43: 0.10863506 | D43: 0.10172521 | E43: 0.099563383 | P43: 0.019247124 | Q43: 3.8221822 | Y43: 4132 | Z43: 0.0953794 | AB43: =IFERROR(D43/O43-1,"") | AC43: =IFERROR(E43/O43-1,"") | AD43: =IFERROR(E43/U43-1,"") | AE43: =IFERROR(Z43/AA43-1,"")

Sheet IBK_N1
A1: IBK N1
A2: Interbank, nodo N1
A4: codmes | B4: n | C4: PD sin calibrar | D4: PD cal vigente | E4: PD cal NUEVA | F4: mora 3m | G4: mora 4m | H4: mora 5m | I4: mora 6m | J4: mora 7m | K4: mora 8m | L4: mora 9m | M4: mora 10m | N4: mora 11m | O4: mora 12m | P4: ft ciclo | Q4: inflacion % | R4: madurez | S4: mora base | T4: factor h->12 | U4: proy mediana | V4: proy V1 | W4: proy V2 | X4: proy V3 | Y4: n visible IBK | Z4: PD cal NUEVA visible | AA4: mora 12m visible | AB4: EC vigente | AC4: EC NUEVA | AD4: EC NUEVA vs proy | AE4: EC NUEVA visible
A5: 202303 | B5: 547 | C5: 0.06458557 | D5: 0.078379974 | E5: 0.045464641 | F5: 0 | G5: 0 | H5: 0.0036563071 | I5: 0.012797075 | J5: 0.020109689 | K5: 0.02559415 | L5: 0.034734918 | M5: 0.036563071 | N5: 0.045703839 | O5: 0.053016453 | P5: 0.23130779 | Q5: 8.6661549 | R5: 12 | S5: 0.053016453 | T5: 1 | U5: 0.053016453 | Y5: 547 | Z5: 0.045464641 | AA5: 0.053016453 | AB5: =IFERROR(D5/O5-1,"") | AC5: =IFERROR(E5/O5-1,"") | AD5: =IFERROR(E5/U5-1,"") | AE5: =IFERROR(Z5/AA5-1,"")
A6: 202304 | B6: 639 | C6: 0.061598889 | D6: 0.075066159 | E6: 0.041910253 | F6: 0.0015649452 | G6: 0.0062597809 | H6: 0.0078247261 | I6: 0.012519562 | J6: 0.015649452 | K6: 0.018779343 | L6: 0.026604069 | M6: 0.028169014 | N6: 0.034428795 | O6: 0.03599374 | P6: 0.20398831 | Q6: 8.0421126 | R6: 12 | S6: 0.03599374 | T6: 1 | U6: 0.03599374 | Y6: 639 | Z6: 0.041910253 | AA6: 0.03599374 | AB6: =IFERROR(D6/O6-1,"") | AC6: =IFERROR(E6/O6-1,"") | AD6: =IFERROR(E6/U6-1,"") | AE6: =IFERROR(Z6/AA6-1,"")
A7: 202305 | B7: 746 | C7: 0.065038101 | D7: 0.078119894 | E7: 0.046525449 | F7: 0.0026809651 | G7: 0.0080428954 | H7: 0.012064343 | I7: 0.018766756 | J7: 0.021447721 | K7: 0.029490617 | L7: 0.034852547 | M7: 0.037533512 | N7: 0.042895442 | O7: 0.045576408 | P7: 0.20154202 | Q7: 7.9862335 | R7: 12 | S7: 0.045576408 | T7: 1 | U7: 0.045576408 | Y7: 746 | Z7: 0.046525449 | AA7: 0.045576408 | AB7: =IFERROR(D7/O7-1,"") | AC7: =IFERROR(E7/O7-1,"") | AD7: =IFERROR(E7/U7-1,"") | AE7: =IFERROR(Z7/AA7-1,"")
A8: 202306 | B8: 674 | C8: 0.060066591 | D8: 0.072297283 | E8: 0.040941053 | F8: 0.0029673591 | G8: 0.010385757 | H8: 0.011869436 | I8: 0.017804154 | J8: 0.022255193 | K8: 0.035608309 | L8: 0.040059347 | M8: 0.041543027 | N8: 0.044510386 | O8: 0.045994065 | P8: 0.14563116 | Q8: 6.7090957 | R8: 12 | S8: 0.045994065 | T8: 1 | U8: 0.045994065 | Y8: 674 | Z8: 0.040941053 | AA8: 0.045994065 | AB8: =IFERROR(D8/O8-1,"") | AC8: =IFERROR(E8/O8-1,"") | AD8: =IFERROR(E8/U8-1,"") | AE8: =IFERROR(Z8/AA8-1,"")
A9: 202307 | B9: 558 | C9: 0.055011289 | D9: 0.058060052 | E9: 0.034157772 | F9: 0.0017921147 | G9: 0.0053763441 | H9: 0.0071684588 | I9: 0.010752688 | J9: 0.016129032 | K9: 0.017921147 | L9: 0.021505376 | M9: 0.023297491 | N9: 0.028673835 | O9: 0.035842294 | P9: 0.11544766 | Q9: 6.0196325 | R9: 12 | S9: 0.035842294 | T9: 1 | U9: 0.035842294 | Y9: 558 | Z9: 0.034157772 | AA9: 0.035842294 | AB9: =IFERROR(D9/O9-1,"") | AC9: =IFERROR(E9/O9-1,"") | AD9: =IFERROR(E9/U9-1,"") | AE9: =IFERROR(Z9/AA9-1,"")
A10: 202308 | B10: 784 | C10: 0.073096935 | D10: 0.077683219 | E10: 0.055724923 | F10: 0.0012755102 | G10: 0.0038265306 | H10: 0.014030612 | I10: 0.017857143 | J10: 0.025510204 | K10: 0.031887755 | L10: 0.038265306 | M10: 0.042091837 | N10: 0.042091837 | O10: 0.044642857 | P10: 0.10524205 | Q10: 5.7865118 | R10: 12 | S10: 0.044642857 | T10: 1 | U10: 0.044642857 | Y10: 784 | Z10: 0.055724923 | AA10: 0.044642857 | AB10: =IFERROR(D10/O10-1,"") | AC10: =IFERROR(E10/O10-1,"") | AD10: =IFERROR(E10/U10-1,"") | AE10: =IFERROR(Z10/AA10-1,"")
A11: 202309 | B11: 506 | C11: 0.067996993 | D11: 0.062297749 | E11: 0.048910157 | F11: 0.0019762846 | G11: 0.0059288538 | H11: 0.0098814229 | I11: 0.019762846 | J11: 0.023715415 | K11: 0.035573123 | L11: 0.041501976 | M11: 0.04743083 | N11: 0.053359684 | O11: 0.057312253 | P11: 0.082642878 | Q11: 5.2702928 | R11: 12 | S11: 0.057312253 | T11: 1 | U11: 0.057312253 | Y11: 506 | Z11: 0.048910157 | AA11: 0.057312253 | AB11: =IFERROR(D11/O11-1,"") | AC11: =IFERROR(E11/O11-1,"") | AD11: =IFERROR(E11/U11-1,"") | AE11: =IFERROR(Z11/AA11-1,"")
A12: 202310 | B12: 390 | C12: 0.057893398 | D12: 0.054934826 | E12: 0.034631855 | F12: 0 | G12: 0.0076923077 | H12: 0.0076923077 | I12: 0.01025641 | J12: 0.017948718 | K12: 0.020512821 | L12: 0.020512821 | M12: 0.023076923 | N12: 0.025641026 | O12: 0.030769231 | P12: 0.049681202 | Q12: 4.5173693 | R12: 12 | S12: 0.030769231 | T12: 1 | U12: 0.030769231 | Y12: 390 | Z12: 0.034631855 | AA12: 0.030769231 | AB12: =IFERROR(D12/O12-1,"") | AC12: =IFERROR(E12/O12-1,"") | AD12: =IFERROR(E12/U12-1,"") | AE12: =IFERROR(Z12/AA12-1,"")
A13: 202311 | B13: 413 | C13: 0.12342747 | D13: 0.12370119 | E13: 0.11190965 | F13: 0.0024213075 | G13: 0.024213075 | H13: 0.046004843 | I13: 0.060532688 | J13: 0.07748184 | K13: 0.092009685 | L13: 0.0968523 | M13: 0.10653753 | N13: 0.11864407 | O13: 0.13075061 | P13: 0.017692212 | Q13: 3.7866642 | R13: 12 | S13: 0.13075061 | T13: 1 | U13: 0.13075061 | Y13: 413 | Z13: 0.11190965 | AA13: 0.13075061 | AB13: =IFERROR(D13/O13-1,"") | AC13: =IFERROR(E13/O13-1,"") | AD13: =IFERROR(E13/U13-1,"") | AE13: =IFERROR(Z13/AA13-1,"")
A14: 202312 | B14: 622 | C14: 0.13148555 | D14: 0.13140286 | E14: 0.11869668 | F14: 0.0048231511 | G14: 0.02733119 | H14: 0.045016077 | I14: 0.059485531 | J14: 0.067524116 | K14: 0.075562701 | L14: 0.078778135 | M14: 0.081993569 | N14: 0.096463023 | O14: 0.10128617 | P14: 0.0012463847 | Q14: 3.4110022 | R14: 12 | S14: 0.10128617 | T14: 1 | U14: 0.10128617 | Y14: 622 | Z14: 0.11869668 | AA14: 0.10128617 | AB14: =IFERROR(D14/O14-1,"") | AC14: =IFERROR(E14/O14-1,"") | AD14: =IFERROR(E14/U14-1,"") | AE14: =IFERROR(Z14/AA14-1,"")
A15: 202401 | B15: 858 | C15: 0.10240321 | D15: 0.093820201 | E15: 0.079469767 | F15: 0.0046620047 | G15: 0.017482517 | H15: 0.03030303 | I15: 0.037296037 | J15: 0.03962704 | K15: 0.045454545 | L15: 0.048951049 | M15: 0.055944056 | N15: 0.061771562 | O15: 0.068764569 | P15: -0.019064283 | Q15: 2.947058 | R15: 12 | S15: 0.068764569 | T15: 1 | U15: 0.068764569 | Y15: 858 | Z15: 0.079469767 | AA15: 0.068764569 | AB15: =IFERROR(D15/O15-1,"") | AC15: =IFERROR(E15/O15-1,"") | AD15: =IFERROR(E15/U15-1,"") | AE15: =IFERROR(Z15/AA15-1,"")
A16: 202402 | B16: 768 | C16: 0.10745189 | D16: 0.09841271 | E16: 0.086159465 | F16: 0.0078125 | G16: 0.01953125 | H16: 0.03515625 | I16: 0.044270833 | J16: 0.053385417 | K16: 0.069010417 | L16: 0.080729167 | M16: 0.092447917 | N16: 0.10286458 | O16: 0.11067708 | P16: -0.019828668 | Q16: 2.9295976 | R16: 12 | S16: 0.11067708 | T16: 1 | U16: 0.11067708 | Y16: 768 | Z16: 0.086159465 | AA16: 0.11067708 | AB16: =IFERROR(D16/O16-1,"") | AC16: =IFERROR(E16/O16-1,"") | AD16: =IFERROR(E16/U16-1,"") | AE16: =IFERROR(Z16/AA16-1,"")
... A32: 202506 | B32: 509 | C32: 0.06878093 | D32: 0.063699996 | E32: 0.036090685 | F32: 0 | G32: 0 | H32: 0.0039292731 | I32: 0.0078585462 | J32: 0.0098231827 | K32: 0.015717092 | L32: 0.017681729 | M32: 0.019646365 | N32: 0.021611002 | O32: 0.021611002 | P32: -0.073765695 | Q32: 1.697547 | R32: 12 | S32: 0.021611002 | T32: 1 | U32: 0.021611002 | Y32: 509 | Z32: 0.036090685 | AA32: 0.021611002 | AB32: =IFERROR(D32/O32-1,"") | AC32: =IFERROR(E32/O32-1,"") | AD32: =IFERROR(E32/U32-1,"") | AE32: =IFERROR(Z32/AA32-1,"")
A33: 202507 | B33: 561 | C33: 0.070563703 | D33: 0.065388718 | E33: 0.037468413 | F33: 0 | G33: 0.0017825312 | H33: 0.0035650624 | I33: 0.0035650624 | J33: 0.0053475936 | K33: 0.0071301248 | L33: 0.008912656 | M33: 0.012477718 | N33: 0.016042781 | P33: -0.073640896 | Q33: 1.7003977 | R33: 11 | S33: 0.016042781 | T33: 1.0953947 | U33: 0.017573178 | V33: 0.016726343 | W33: 0.017124453 | X33: 0.01824298 | Y33: 561 | Z33: 0.037468413 | AB33: =IFERROR(D33/O33-1,"") | AC33: =IFERROR(E33/O33-1,"") | AD33: =IFERROR(E33/U33-1,"") | AE33: =IFERROR(Z33/AA33-1,"")
A34: 202508 | B34: 651 | C34: 0.070092345 | D34: 0.064645414 | E34: 0.036383362 | F34: 0.0030721966 | G34: 0.0046082949 | H34: 0.010752688 | I34: 0.012288786 | J34: 0.012288786 | K34: 0.016897081 | L34: 0.01843318 | M34: 0.024577573 | P34: -0.10033144 | Q34: 1.0907218 | R34: 10 | S34: 0.024577573 | T34: 1.2742347 | U34: 0.031317596 | V34: 0.029629389 | W34: 0.030674774 | X34: 0.032770097 | Y34: 651 | Z34: 0.036383362 | AB34: =IFERROR(D34/O34-1,"") | AC34: =IFERROR(E34/O34-1,"") | AD34: =IFERROR(E34/U34-1,"") | AE34: =IFERROR(Z34/AA34-1,"")
A35: 202509 | B35: 592 | C35: 0.06672043 | D35: 0.061585114 | E35: 0.032372495 | F35: 0 | G35: 0.0033783784 | H35: 0.0067567568 | I35: 0.0067567568 | J35: 0.010135135 | K35: 0.011824324 | L35: 0.013513514 | P35: -0.094338164 | Q35: 1.2276226 | R35: 9 | S35: 0.013513514 | T35: 1.4210526 | U35: 0.019203414 | V35: 0.018018018 | W35: 0.019114894 | X35: 0.020778297 | Y35: 592 | Z35: 0.032372495 | AB35: =IFERROR(D35/O35-1,"") | AC35: =IFERROR(E35/O35-1,"") | AD35: =IFERROR(E35/U35-1,"") | AE35: =IFERROR(Z35/AA35-1,"")
A36: 202510 | B36: 600 | C36: 0.071445585 | D36: 0.066184865 | E36: 0.036855367 | F36: 0.0016666667 | G36: 0.0033333333 | H36: 0.0066666667 | I36: 0.0083333333 | J36: 0.0083333333 | K36: 0.011666667 | P36: -0.097186463 | Q36: 1.1625606 | R36: 8 | S36: 0.011666667 | T36: 1.6567164 | U36: 0.019328358 | V36: 0.017612179 | W36: 0.0195125 | X36: 0.022388117 | Y36: 600 | Z36: 0.036855367 | AB36: =IFERROR(D36/O36-1,"") | AC36: =IFERROR(E36/O36-1,"") | AD36: =IFERROR(E36/U36-1,"") | AE36: =IFERROR(Z36/AA36-1,"")
A37: 202511 | B37: 525 | C37: 0.069606633 | D37: 0.064674429 | E37: 0.035126754 | F37: 0 | G37: 0.0038095238 | H37: 0.0057142857 | I37: 0.017142857 | J37: 0.019047619 | P37: -0.095195045 | Q37: 1.2080494 | R37: 7 | S37: 0.019047619 | T37: 2.068323 | U37: 0.039396628 | V37: 0.037414966 | W37: 0.041190476 | X37: 0.04482684 | Y37: 525 | Z37: 0.035126754 | AB37: =IFERROR(D37/O37-1,"") | AC37: =IFERROR(E37/O37-1,"") | AD37: =IFERROR(E37/U37-1,"") | AE37: =IFERROR(Z37/AA37-1,"")
A38: 202512 | B38: 538 | C38: 0.078449248 | D38: 0.073034969 | E38: 0.043669776 | F38: 0.0018587361 | G38: 0.0037174721 | H38: 0.0055762082 | I38: 0.0074349442 | P38: -0.090738963 | Q38: 1.3098369 | R38: 6 | S38: 0.0074349442 | T38: 2.6015625 | U38: 0.019342472 | V38: 0.018454594 | W38: 0.020213755 | X38: 0.023215613 | Y38: 538 | Z38: 0.043669776 | AB38: =IFERROR(D38/O38-1,"") | AC38: =IFERROR(E38/O38-1,"") | AD38: =IFERROR(E38/U38-1,"") | AE38: =IFERROR(Z38/AA38-1,"")
A39: 202601 | B39: 656 | C39: 0.071884733 | D39: 0.066606593 | E39: 0.037285058 | F39: 0.0015243902 | G39: 0.0015243902 | H39: 0.0076219512 | P39: -0.082751237 | Q39: 1.4922957 | R39: 5 | S39: 0.0076219512 | T39: 3.6863469 | U39: 0.028097156 | V39: 0.024641422 | W39: 0.031546409 | X39: 0.040015244 | Y39: 656 | Z39: 0.037285058 | AB39: =IFERROR(D39/O39-1,"") | AC39: =IFERROR(E39/O39-1,"") | AD39: =IFERROR(E39/U39-1,"") | AE39: =IFERROR(Z39/AA39-1,"")
A40: 202602 | B40: 607 | C40: 0.072678548 | D40: 0.066877625 | E40: 0.041506508 | F40: 0.0016474465 | G40: 0.0016474465 | P40: -0.037038893 | Q40: 2.5364749 | R40: 4 | S40: 0.0016474465 | T40: 6.0696203 | U40: 0.0099993744 | V40: 0.0088138386 | W40: 0.010414215 | X40: 0.016831411 | Y40: 607 | Z40: 0.041506508 | AB40: =IFERROR(D40/O40-1,"") | AC40: =IFERROR(E40/O40-1,"") | AD40: =IFERROR(E40/U40-1,"") | AE40: =IFERROR(Z40/AA40-1,"")
A41: 202603 | B41: 698 | C41: 0.068862964 | D41: 0.063474054 | E41: 0.041229335 | F41: 0 | P41: 0.014389803 | Q41: 3.7112293 | R41: 3 | S41: 0 | T41: 19.022222 | U41: 0 | V41: 0 | W41: 0 | X41: 0 | Y41: 698 | Z41: 0.041229335 | AB41: =IFERROR(D41/O41-1,"") | AC41: =IFERROR(E41/O41-1,"") | AD41: =IFERROR(E41/U41-1,"") | AE41: =IFERROR(Z41/AA41-1,"")
A42: 202604 | B42: 602 | C42: 0.065371956 | D42: 0.060103768 | E42: 0.037920143 | P42: 0.024185191 | Q42: 3.9349794 | Y42: 602 | Z42: 0.037920143 | AB42: =IFERROR(D42/O42-1,"") | AC42: =IFERROR(E42/O42-1,"") | AD42: =IFERROR(E42/U42-1,"") | AE42: =IFERROR(Z42/AA42-1,"")
A43: 202605 | B43: 608 | C43: 0.071671278 | D43: 0.065289819 | E43: 0.044664622 | P43: 0.019247124 | Q43: 3.8221822 | Y43: 608 | Z43: 0.044664622 | AB43: =IFERROR(D43/O43-1,"") | AC43: =IFERROR(E43/O43-1,"") | AD43: =IFERROR(E43/U43-1,"") | AE43: =IFERROR(Z43/AA43-1,"")

Sheet IBK_N2
A1: IBK N2
A2: Interbank, nodo N2
A4: codmes | B4: n | C4: PD sin calibrar | D4: PD cal vigente | E4: PD cal NUEVA | F4: mora 3m | G4: mora 4m | H4: mora 5m | I4: mora 6m | J4: mora 7m | K4: mora 8m | L4: mora 9m | M4: mora 10m | N4: mora 11m | O4: mora 12m | P4: ft ciclo | Q4: inflacion % | R4: madurez | S4: mora base | T4: factor h->12 | U4: proy mediana | V4: proy V1 | W4: proy V2 | X4: proy V3 | Y4: n visible IBK | Z4: PD cal NUEVA visible | AA4: mora 12m visible | AB4: EC vigente | AC4: EC NUEVA | AD4: EC NUEVA vs proy | AE4: EC NUEVA visible
A5: 202303 | B5: 2129 | C5: 0.10951389 | D5: 0.13796817 | E5: 0.095852056 | F5: 0.0046970409 | G5: 0.021606388 | H5: 0.036167215 | I5: 0.047909817 | J5: 0.063879756 | K5: 0.080319399 | L5: 0.093940817 | M5: 0.10662283 | N5: 0.1146078 | O5: 0.1258807 | P5: 0.23130779 | Q5: 8.6661549 | R5: 12 | S5: 0.1258807 | T5: 1 | U5: 0.1258807 | Y5: 2129 | Z5: 0.095852056 | AA5: 0.1258807 | AB5: =IFERROR(D5/O5-1,"") | AC5: =IFERROR(E5/O5-1,"") | AD5: =IFERROR(E5/U5-1,"") | AE5: =IFERROR(Z5/AA5-1,"")
A6: 202304 | B6: 2131 | C6: 0.10361779 | D6: 0.13117086 | E6: 0.089440401 | F6: 0.0065696856 | G6: 0.019239794 | H6: 0.029563585 | I6: 0.044580009 | J6: 0.057719381 | K6: 0.070389489 | L6: 0.084936649 | M6: 0.098076021 | N6: 0.10886908 | O6: 0.11731581 | P6: 0.20398831 | Q6: 8.0421126 | R6: 12 | S6: 0.11731581 | T6: 1 | U6: 0.11731581 | Y6: 2131 | Z6: 0.089440401 | AA6: 0.11731581 | AB6: =IFERROR(D6/O6-1,"") | AC6: =IFERROR(E6/O6-1,"") | AD6: =IFERROR(E6/U6-1,"") | AE6: =IFERROR(Z6/AA6-1,"")
A7: 202305 | B7: 2511 | C7: 0.10671639 | D7: 0.13473184 | E7: 0.092859698 | F7: 0.0047789725 | G7: 0.022301872 | H7: 0.036240542 | I7: 0.050179211 | J7: 0.066507368 | K7: 0.081640781 | L7: 0.091995221 | M7: 0.10593389 | N7: 0.11469534 | O7: 0.11987256 | P7: 0.20154202 | Q7: 7.9862335 | R7: 12 | S7: 0.11987256 | T7: 1 | U7: 0.11987256 | Y7: 2511 | Z7: 0.092859698 | AA7: 0.11987256 | AB7: =IFERROR(D7/O7-1,"") | AC7: =IFERROR(E7/O7-1,"") | AD7: =IFERROR(E7/U7-1,"") | AE7: =IFERROR(Z7/AA7-1,"")
A8: 202306 | B8: 1808 | C8: 0.10047568 | D8: 0.12690394 | E8: 0.086118474 | F8: 0.0077433628 | G8: 0.012721239 | H8: 0.03539823 | I8: 0.049225664 | J8: 0.059734513 | K8: 0.075221239 | L8: 0.087389381 | M8: 0.097345133 | N8: 0.10896018 | O8: 0.11449115 | P8: 0.14563116 | Q8: 6.7090957 | R8: 12 | S8: 0.11449115 | T8: 1 | U8: 0.11449115 | Y8: 1808 | Z8: 0.086118474 | AA8: 0.11449115 | AB8: =IFERROR(D8/O8-1,"") | AC8: =IFERROR(E8/O8-1,"") | AD8: =IFERROR(E8/U8-1,"") | AE8: =IFERROR(Z8/AA8-1,"")
A9: 202307 | B9: 1213 | C9: 0.083441289 | D9: 0.085794547 | E9: 0.066802135 | F9: 0.0024732069 | G9: 0.01071723 | H9: 0.015663644 | I9: 0.022258862 | J9: 0.026380874 | K9: 0.034624897 | L9: 0.037922506 | M9: 0.043693322 | N9: 0.051112943 | O9: 0.05358615 | P9: 0.11544766 | Q9: 6.0196325 | R9: 12 | S9: 0.05358615 | T9: 1 | U9: 0.05358615 | Y9: 1213 | Z9: 0.066802135 | AA9: 0.05358615 | AB9: =IFERROR(D9/O9-1,"") | AC9: =IFERROR(E9/O9-1,"") | AD9: =IFERROR(E9/U9-1,"") | AE9: =IFERROR(Z9/AA9-1,"")
A10: 202308 | B10: 1418 | C10: 0.087107787 | D10: 0.089627009 | E10: 0.070301313 | F10: 0.0049365303 | G10: 0.011283498 | H10: 0.016220028 | I10: 0.02045134 | J10: 0.026798307 | K10: 0.034555712 | L10: 0.039492243 | M10: 0.044428773 | N10: 0.048660085 | O10: 0.052891396 | P10: 0.10524205 | Q10: 5.7865118 | R10: 12 | S10: 0.052891396 | T10: 1 | U10: 0.052891396 | Y10: 1418 | Z10: 0.070301313 | AA10: 0.052891396 | AB10: =IFERROR(D10/O10-1,"") | AC10: =IFERROR(E10/O10-1,"") | AD10: =IFERROR(E10/U10-1,"") | AE10: =IFERROR(Z10/AA10-1,"")
A11: 202309 | B11: 919 | C11: 0.084266115 | D11: 0.080106029 | E11: 0.065379588 | F11: 0.0010881393 | G11: 0.0097932535 | H11: 0.013057671 | I11: 0.019586507 | J11: 0.028291621 | K11: 0.033732318 | L11: 0.040261153 | M11: 0.044613711 | N11: 0.046789989 | O11: 0.052230686 | P11: 0.082642878 | Q11: 5.2702928 | R11: 12 | S11: 0.052230686 | T11: 1 | U11: 0.052230686 | Y11: 919 | Z11: 0.065379588 | AA11: 0.052230686 | AB11: =IFERROR(D11/O11-1,"") | AC11: =IFERROR(E11/O11-1,"") | AD11: =IFERROR(E11/U11-1,"") | AE11: =IFERROR(Z11/AA11-1,"")
A12: 202310 | B12: 888 | C12: 0.087891235 | D12: 0.088644015 | E12: 0.065449989 | F12: 0.0022522523 | G12: 0.009009009 | H12: 0.018018018 | I12: 0.025900901 | J12: 0.03490991 | K12: 0.040540541 | L12: 0.048423423 | M12: 0.054054054 | N12: 0.058558559 | O12: 0.063063063 | P12: 0.049681202 | Q12: 4.5173693 | R12: 12 | S12: 0.063063063 | T12: 1 | U12: 0.063063063 | Y12: 888 | Z12: 0.065449989 | AA12: 0.063063063 | AB12: =IFERROR(D12/O12-1,"") | AC12: =IFERROR(E12/O12-1,"") | AD12: =IFERROR(E12/U12-1,"") | AE12: =IFERROR(Z12/AA12-1,"")
A13: 202311 | B13: 828 | C13: 0.11543075 | D13: 0.11700124 | E13: 0.088990434 | F13: 0.0012077295 | G13: 0.015700483 | H13: 0.036231884 | I13: 0.047101449 | J13: 0.062801932 | K13: 0.076086957 | L13: 0.080917874 | M13: 0.09057971 | N13: 0.094202899 | O13: 0.097826087 | P13: 0.017692212 | Q13: 3.7866642 | R13: 12 | S13: 0.097826087 | T13: 1 | U13: 0.097826087 | Y13: 828 | Z13: 0.088990434 | AA13: 0.097826087 | AB13: =IFERROR(D13/O13-1,"") | AC13: =IFERROR(E13/O13-1,"") | AD13: =IFERROR(E13/U13-1,"") | AE13: =IFERROR(Z13/AA13-1,"")
A14: 202312 | B14: 896 | C14: 0.13810363 | D14: 0.13941653 | E14: 0.10866352 | F14: 0.013392857 | G14: 0.033482143 | H14: 0.060267857 | I14: 0.072544643 | J14: 0.083705357 | K14: 0.094866071 | L14: 0.10267857 | M14: 0.10714286 | N14: 0.12053571 | O14: 0.13058036 | P14: 0.0012463847 | Q14: 3.4110022 | R14: 12 | S14: 0.13058036 | T14: 1 | U14: 0.13058036 | Y14: 896 | Z14: 0.10866352 | AA14: 0.13058036 | AB14: =IFERROR(D14/O14-1,"") | AC14: =IFERROR(E14/O14-1,"") | AD14: =IFERROR(E14/U14-1,"") | AE14: =IFERROR(Z14/AA14-1,"")
A15: 202401 | B15: 1016 | C15: 0.11997624 | D15: 0.11298579 | E15: 0.088299158 | F15: 0.0088582677 | G15: 0.028543307 | H15: 0.042322835 | I15: 0.05511811 | J15: 0.058070866 | K15: 0.061023622 | L15: 0.066929134 | M15: 0.076771654 | N15: 0.083661417 | O15: 0.090551181 | P15: -0.019064283 | Q15: 2.947058 | R15: 12 | S15: 0.090551181 | T15: 1 | U15: 0.090551181 | Y15: 1016 | Z15: 0.088299158 | AA15: 0.090551181 | AB15: =IFERROR(D15/O15-1,"") | AC15: =IFERROR(E15/O15-1,"") | AD15: =IFERROR(E15/U15-1,"") | AE15: =IFERROR(Z15/AA15-1,"")
A16: 202402 | B16: 1020 | C16: 0.12228091 | D16: 0.11514337 | E16: 0.090233298 | F16: 0.0098039216 | G16: 0.02745098 | H16: 0.033333333 | I16: 0.041176471 | J16: 0.047058824 | K16: 0.05 | L16: 0.056862745 | M16: 0.067647059 | N16: 0.075490196 | O16: 0.083333333 | P16: -0.019828668 | Q16: 2.9295976 | R16: 12 | S16: 0.083333333 | T16: 1 | U16: 0.083333333 | Y16: 1020 | Z16: 0.090233298 | AA16: 0.083333333 | AB16: =IFERROR(D16/O16-1,"") | AC16: =IFERROR(E16/O16-1,"") | AD16: =IFERROR(E16/U16-1,"") | AE16: =IFERROR(Z16/AA16-1,"")
... A32: 202506 | B32: 631 | C32: 0.081967843 | D32: 0.078228992 | E32: 0.047372802 | F32: 0.0063391442 | G32: 0.012678288 | H32: 0.022187005 | I32: 0.026941363 | J32: 0.034865293 | K32: 0.04437401 | L32: 0.045958796 | M32: 0.050713154 | N32: 0.053882726 | O32: 0.055467512 | P32: -0.073765695 | Q32: 1.697547 | R32: 12 | S32: 0.055467512 | T32: 1 | U32: 0.055467512 | Y32: 631 | Z32: 0.047372802 | AA32: 0.055467512 | AB32: =IFERROR(D32/O32-1,"") | AC32: =IFERROR(E32/O32-1,"") | AD32: =IFERROR(E32/U32-1,"") | AE32: =IFERROR(Z32/AA32-1,"")
A33: 202507 | B33: 769 | C33: 0.089751887 | D33: 0.085792041 | E33: 0.053507904 | F33: 0.0052015605 | G33: 0.014304291 | H33: 0.024707412 | I33: 0.027308192 | J33: 0.035110533 | K33: 0.039011704 | L33: 0.046814044 | M33: 0.055916775 | N33: 0.055916775 | P33: -0.073640896 | Q33: 1.7003977 | R33: 11 | S33: 0.055916775 | T33: 1.0830465 | U33: 0.060560466 | V33: 0.059489236 | W33: 0.060412045 | X33: 0.062201994 | Y33: 769 | Z33: 0.053507904 | AB33: =IFERROR(D33/O33-1,"") | AC33: =IFERROR(E33/O33-1,"") | AD33: =IFERROR(E33/U33-1,"") | AE33: =IFERROR(Z33/AA33-1,"")
A34: 202508 | B34: 709 | C34: 0.088665799 | D34: 0.084520242 | E34: 0.05178037 | F34: 0.0028208745 | G34: 0.012693935 | H34: 0.01551481 | I34: 0.021156559 | J34: 0.02538787 | K34: 0.029619182 | L34: 0.036671368 | M34: 0.038081805 | P34: -0.10033144 | Q34: 1.0907218 | R34: 10 | S34: 0.038081805 | T34: 1.1900709 | U34: 0.045320049 | V34: 0.044544876 | W34: 0.045443941 | X34: 0.046952612 | Y34: 709 | Z34: 0.05178037 | AB34: =IFERROR(D34/O34-1,"") | AC34: =IFERROR(E34/O34-1,"") | AD34: =IFERROR(E34/U34-1,"") | AE34: =IFERROR(Z34/AA34-1,"")
A35: 202509 | B35: 752 | C35: 0.089500488 | D35: 0.085217064 | E35: 0.052911594 | F35: 0.0066489362 | G35: 0.010638298 | H35: 0.017287234 | I35: 0.021276596 | J35: 0.022606383 | K35: 0.02393617 | L35: 0.02393617 | P35: -0.094338164 | Q35: 1.2276226 | R35: 9 | S35: 0.02393617 | T35: 1.3452699 | U35: 0.03220061 | V35: 0.030899388 | W35: 0.032091982 | X35: 0.034223024 | Y35: 752 | Z35: 0.052911594 | AB35: =IFERROR(D35/O35-1,"") | AC35: =IFERROR(E35/O35-1,"") | AD35: =IFERROR(E35/U35-1,"") | AE35: =IFERROR(Z35/AA35-1,"")
A36: 202510 | B36: 795 | C36: 0.084440106 | D36: 0.080464165 | E36: 0.048294786 | F36: 0.0012578616 | G36: 0.011320755 | H36: 0.018867925 | I36: 0.022641509 | J36: 0.026415094 | K36: 0.032704403 | P36: -0.097186463 | Q36: 1.1625606 | R36: 8 | S36: 0.032704403 | T36: 1.5489231 | U36: 0.050656604 | V36: 0.047824649 | W36: 0.050756295 | X36: 0.054610182 | Y36: 795 | Z36: 0.048294786 | AB36: =IFERROR(D36/O36-1,"") | AC36: =IFERROR(E36/O36-1,"") | AD36: =IFERROR(E36/U36-1,"") | AE36: =IFERROR(Z36/AA36-1,"")
A37: 202511 | B37: 699 | C37: 0.089092401 | D37: 0.085098855 | E37: 0.05261295 | F37: 0 | G37: 0.012875536 | H37: 0.015736767 | I37: 0.017167382 | J37: 0.017167382 | P37: -0.095195045 | Q37: 1.2080494 | R37: 7 | S37: 0.017167382 | T37: 1.8603104 | U37: 0.03193666 | V37: 0.027179087 | W37: 0.032298889 | X37: 0.034876697 | Y37: 699 | Z37: 0.05261295 | AB37: =IFERROR(D37/O37-1,"") | AC37: =IFERROR(E37/O37-1,"") | AD37: =IFERROR(E37/U37-1,"") | AE37: =IFERROR(Z37/AA37-1,"")
A38: 202512 | B38: 785 | C38: 0.092837411 | D38: 0.088446975 | E38: 0.05583896 | F38: 0.0063694268 | G38: 0.014012739 | H38: 0.020382166 | I38: 0.029299363 | P38: -0.090738963 | Q38: 1.3098369 | R38: 6 | S38: 0.029299363 | T38: 2.3049451 | U38: 0.067533422 | V38: 0.060065746 | W38: 0.069069316 | X38: 0.077012877 | Y38: 784 | Z38: 0.055781154 | AB38: =IFERROR(D38/O38-1,"") | AC38: =IFERROR(E38/O38-1,"") | AD38: =IFERROR(E38/U38-1,"") | AE38: =IFERROR(Z38/AA38-1,"")
A39: 202601 | B39: 930 | C39: 0.087904403 | D39: 0.083975671 | E39: 0.051561874 | F39: 0.0064516129 | G39: 0.015053763 | H39: 0.020430108 | P39: -0.082751237 | Q39: 1.4922957 | R39: 5 | S39: 0.020430108 | T39: 3.0252404 | U39: 0.061805986 | V39: 0.051075269 | W39: 0.062992832 | X39: 0.071206885 | Y39: 930 | Z39: 0.051561874 | AB39: =IFERROR(D39/O39-1,"") | AC39: =IFERROR(E39/O39-1,"") | AD39: =IFERROR(E39/U39-1,"") | AE39: =IFERROR(Z39/AA39-1,"")
A40: 202602 | B40: 878 | C40: 0.084767441 | D40: 0.080692672 | E40: 0.052930633 | F40: 0.0045558087 | G40: 0.0091116173 | P40: -0.037038893 | Q40: 2.5364749 | R40: 4 | S40: 0.0091116173 | T40: 5.0139442 | U40: 0.045685141 | V40: 0.039147413 | W40: 0.046630042 | X40: 0.050368568 | Y40: 878 | Z40: 0.052930633 | AB40: =IFERROR(D40/O40-1,"") | AC40: =IFERROR(E40/O40-1,"") | AD40: =IFERROR(E40/U40-1,"") | AE40: =IFERROR(Z40/AA40-1,"")
A41: 202603 | B41: 913 | C41: 0.090583605 | D41: 0.086400115 | E41: 0.063266211 | F41: 0.0010952903 | P41: 0.014389803 | Q41: 3.7112293 | R41: 3 | S41: 0.0010952903 | T41: 14.830303 | U41: 0.016243486 | V41: 0.010808385 | W41: 0.015946905 | X41: 0.026195692 | Y41: 913 | Z41: 0.063266211 | AB41: =IFERROR(D41/O41-1,"") | AC41: =IFERROR(E41/O41-1,"") | AD41: =IFERROR(E41/U41-1,"") | AE41: =IFERROR(Z41/AA41-1,"")
A42: 202604 | B42: 869 | C42: 0.089478198 | D42: 0.084120645 | E42: 0.06357591 | P42: 0.024185191 | Q42: 3.9349794 | Y42: 869 | Z42: 0.06357591 | AB42: =IFERROR(D42/O42-1,"") | AC42: =IFERROR(E42/O42-1,"") | AD42: =IFERROR(E42/U42-1,"") | AE42: =IFERROR(Z42/AA42-1,"")
A43: 202605 | B43: 955 | C43: 0.09437141 | D43: 0.088262344 | E43: 0.067183211 | P43: 0.019247124 | Q43: 3.8221822 | Y43: 955 | Z43: 0.067183211 | AB43: =IFERROR(D43/O43-1,"") | AC43: =IFERROR(E43/O43-1,"") | AD43: =IFERROR(E43/U43-1,"") | AE43: =IFERROR(Z43/AA43-1,"")

Sheet IBK_N3
A1: IBK N3
A2: Interbank, nodo N3
A4: codmes | B4: n | C4: PD sin calibrar | D4: PD cal vigente | E4: PD cal NUEVA | F4: mora 3m | G4: mora 4m | H4: mora 5m | I4: mora 6m | J4: mora 7m | K4: mora 8m | L4: mora 9m | M4: mora 10m | N4: mora 11m | O4: mora 12m | P4: ft ciclo | Q4: inflacion % | R4: madurez | S4: mora base | T4: factor h->12 | U4: proy mediana | V4: proy V1 | W4: proy V2 | X4: proy V3 | Y4: n visible IBK | Z4: PD cal NUEVA visible | AA4: mora 12m visible | AB4: EC vigente | AC4: EC NUEVA | AD4: EC NUEVA vs proy | AE4: EC NUEVA visible
A5: 202303 | B5: 4071 | C5: 0.1390946 | D5: 0.17540367 | E5: 0.16150717 | F5: 0.017194792 | G5: 0.056988455 | H5: 0.076394006 | I5: 0.10071236 | J5: 0.12331123 | K5: 0.14984033 | L5: 0.16703513 | M5: 0.18251044 | N5: 0.19135348 | O5: 0.19945959 | P5: 0.23130779 | Q5: 8.6661549 | R5: 12 | S5: 0.19945959 | T5: 1 | U5: 0.19945959 | Y5: 3729 | Z5: 0.165028 | AA5: 0.2003218 | AB5: =IFERROR(D5/O5-1,"") | AC5: =IFERROR(E5/O5-1,"") | AD5: =IFERROR(E5/U5-1,"") | AE5: =IFERROR(Z5/AA5-1,"")
A6: 202304 | B6: 3172 | C6: 0.13174628 | D6: 0.16622633 | E6: 0.15188905 | F6: 0.013556116 | G6: 0.048865069 | H6: 0.073139975 | I6: 0.096153846 | J6: 0.11696091 | K6: 0.14186633 | L6: 0.15889029 | M6: 0.17307692 | N6: 0.18253468 | O6: 0.18915511 | P6: 0.20398831 | Q6: 8.0421126 | R6: 12 | S6: 0.18915511 | T6: 1 | U6: 0.18915511 | Y6: 2938 | Z6: 0.15478009 | AA6: 0.19298843 | AB6: =IFERROR(D6/O6-1,"") | AC6: =IFERROR(E6/O6-1,"") | AD6: =IFERROR(E6/U6-1,"") | AE6: =IFERROR(Z6/AA6-1,"")
A7: 202305 | B7: 4160 | C7: 0.13097219 | D7: 0.16563746 | E7: 0.15152322 | F7: 0.013461538 | G7: 0.050480769 | H7: 0.078846154 | I7: 0.10168269 | J7: 0.12307692 | K7: 0.14831731 | L7: 0.16923077 | M7: 0.184375 | N7: 0.19278846 | O7: 0.20072115 | P7: 0.20154202 | Q7: 7.9862335 | R7: 12 | S7: 0.20072115 | T7: 1 | U7: 0.20072115 | Y7: 3813 | Z7: 0.15417759 | AA7: 0.20403881 | AB7: =IFERROR(D7/O7-1,"") | AC7: =IFERROR(E7/O7-1,"") | AD7: =IFERROR(E7/U7-1,"") | AE7: =IFERROR(Z7/AA7-1,"")
